Workbook
Name \: #REF!
Name \0: #REF!
Name \a: #REF!
Name \B: #REF!
Name \B_49_65_: #REF!
Name \BS: #REF!
Name \C: #REF!
Name \C_66_73_: #REF!
Name \d: #REF!
Name \D_SUMMARY_: #REF!
Name \E: #REF!
Name \I: #REF!
Name \M: #REF!
Name \P: #REF!
Name \R: #REF!
Name _______________________F375205: [1]Accounts!#REF!
Name ______________________F375205: [1]Accounts!#REF!
Name _____________________F375205: [1]Accounts!#REF!
Name ____________________F375205: [1]Accounts!#REF!
Name ___________________F375205: [1]Accounts!#REF!
Name __________________F375205: [1]Accounts!#REF!
Name _________________F375205: [2]Accounts!#REF!
Name ________________F375205: [2]Accounts!#REF!
Name _______________F375205: [2]Accounts!#REF!
Name ______________F375205: [3]Accounts!#REF!
Name _____________F375205: [3]Accounts!#REF!
Name _____________vat2: #REF!
Name ____________F375205: [1]Accounts!#REF!
Name ____________vat2: #REF!
Name ___________F375205: [1]Accounts!#REF!
Name ___________vat2: #REF!
Name __________F375205: [1]Accounts!#REF!
Name __________vat2: #REF!
Name _________F375205: [1]Accounts!#REF!
Name _________vat2: #REF!
Name ________F375205: [4]Accounts!#REF!
Name ________vat2: #REF!
Name _______DAT1: '[5]Auditors Assoc'!$A$4:$A$438
Name _______DAT10: '[5]Auditors Assoc'!#REF!
Name _______DAT11: '[5]Auditors Assoc'!#REF!
Name _______DAT12: '[5]Auditors Assoc'!#REF!
Name _______DAT13: '[5]Auditors Assoc'!#REF!
Name _______DAT14: '[5]Auditors Assoc'!#REF!
Name _______DAT15: '[5]Auditors Assoc'!#REF!
Name _______DAT16: '[5]Auditors Assoc'!#REF!
Name _______DAT17: '[5]Auditors Assoc'!$F$4:$F$438
Name _______DAT2: '[5]Auditors Assoc'!$B$4:$B$438
Name _______DAT3: '[5]Auditors Assoc'!#REF!
Name _______DAT4: '[5]Auditors Assoc'!#REF!
Name _______DAT5: '[5]Auditors Assoc'!$C$4:$C$438
Name _______DAT6: '[5]Auditors Assoc'!$D$4:$D$438
Name _______DAT7: '[5]Auditors Assoc'!#REF!
Name _______DAT8: '[5]Auditors Assoc'!#REF!
Name _______DAT9: '[5]Auditors Assoc'!$E$4:$E$438
Name _______F375205: [6]Accounts!#REF!
Name _______vat2: #REF!
Name ______DAT1: '[5]Auditors Assoc'!$A$4:$A$438
Name ______DAT10: '[5]Auditors Assoc'!#REF!
Name ______DAT11: '[5]Auditors Assoc'!#REF!
Name ______DAT12: '[5]Auditors Assoc'!#REF!

Sheet FINAL AFS TB as of 19th Mar 26
C1: Initial submitted to Auditors | D1: Final tie to AFS | E1: Journals Adjustments
C2: 45992 | D2: 45992 | E2: 45992
B3: ='TB December 2025 '!V3 -> 1001 · CDH Inv Bank 0050401042201 | C3: ='Initial TB Submitted to Auditor'!C3 -> 68950246 | D3: 68950246 | E3: =D3-C3 -> 0
B4: ='TB December 2025 '!V4 -> 1002 · CDH Inv Bank PIA 0050401044100 | C4: ='Initial TB Submitted to Auditor'!C4 -> -3276701.7 | D4: -3276701.7 | E4: =D4-C4 -> 0
B5: ='TB December 2025 '!V5 -> 1003 · FDI Project-Payments | C5: ='Initial TB Submitted to Auditor'!C5 -> 0 | D5: 0 | E5: =D5-C5 -> 0
B6: ='TB December 2025 '!V6 -> 1005 · FDI Project payment-USD | C6: ='Initial TB Submitted to Auditor'!C6 -> -4.67 | D6: -4.67 | E6: =D6-C6 -> 0
B7: ='TB December 2025 '!V7 -> 1006 · Petty cash | C7: ='Initial TB Submitted to Auditor'!C7 -> -71515.78 | D7: -71515.78 | E7: =D7-C7 -> 0
B8: ='TB December 2025 '!V8 -> 1012 · Money Market:1008 · Alliance Capital | C8: ='Initial TB Submitted to Auditor'!C8 -> 0 | D8: 0 | E8: =D8-C8 -> 0
B9: ='TB December 2025 '!V9 -> 1012 · Money Market:1009 · CDHIB Fixed Deposit | C9: ='Initial TB Submitted to Auditor'!C9 -> -1.8777713e+09 | D9: -1.8777713e+09 | E9: =D9-C9 -> 0
B10: ='TB December 2025 '!V10 -> 1012 · Money Market:1010 · CDHIB Call Account | C10: ='Initial TB Submitted to Auditor'!C10 -> -33611611 | D10: -33611611 | E10: =D10-C10 -> 0
B11: ='TB December 2025 '!V11 -> 1012 · Money Market:1011 · FDH Discount House | C11: ='Initial TB Submitted to Auditor'!C11 -> -2.6970178e+09 | D11: -2.6970178e+09 | E11: =D11-C11 -> 0
B12: ='TB December 2025 '!V12 -> 1012 · Money Market:1013 · MyBucks | C12: ='Initial TB Submitted to Auditor'!C12 -> 0 | D12: 0 | E12: =D12-C12 -> 0
B13: ='TB December 2025 '!V13 -> 1012 · Money Market:1014 · Continental Asset Management | C13: ='Initial TB Submitted to Auditor'!C13 -> -1.599258e+09 | D13: -1.599258e+09 | E13: =D13-C13 -> 0
B14: ='TB December 2025 '!V14 -> 1012 · Money Market:1015 · NICO-INV1 | C14: ='Initial TB Submitted to Auditor'!C14 -> 0 | D14: 0 | E14: =D14-C14 -> 0
... B42: ='TB December 2025 '!V42 -> 1048 · CDHIB MAIIC AGRA (MK) | C42: ='Initial TB Submitted to Auditor'!C42 -> -36188936 | D42: -36188936 | E42: =D42-C42 -> 0
B43: ='TB December 2025 '!V43 -> 1030 · Partial Credit Guarantee Fund | C43: ='Initial TB Submitted to Auditor'!C43 -> -71808009 | D43: 0 | E43: =D43-C43 -> 71808009 | F43: Reversal of paid agcom fees
B44: ='TB December 2025 '!V44 -> 1039 · Accrued Coupon Settlements | C44: ='Initial TB Submitted to Auditor'!C44 -> -5.3820299e+08 | D44: -5.3820299e+08 | E44: =D44-C44 -> 0
B45: ='TB December 2025 '!V45 -> 1040 · Accrued Interest Income- MM | C45: ='Initial TB Submitted to Auditor'!C45 -> -6.2353678e+08 | D45: -6.38507e+08 | E45: =D45-C45 -> -14970225 | F45: MM Interest adjusment
B46: ='TB December 2025 '!V46 -> 1041 · Accrued Interest income- TNote | C46: ='Initial TB Submitted to Auditor'!C46 -> 0 | D46: 0 | E46: =D46-C46 -> 0
B47: ='TB December 2025 '!V47 -> 1042 · Accrued Interest Income- T/Bill | C47: ='Initial TB Submitted to Auditor'!C47 -> 0 | D47: 0 | E47: =D47-C47 -> 0
B48: ='TB December 2025 '!V48 -> 1049 · Term Loan - USD | C48: ='Initial TB Submitted to Auditor'!C48 -> 0 | D48: 0 | E48: =D48-C48 -> 0
B49: ='TB December 2025 '!V49 -> 1050 · Term Loans | C49: ='Initial TB Submitted to Auditor'!C49 -> -1.4702425e+10 | D49: -1.4702425e+10 | E49: =D49-C49 -> 0
B50: ='TB December 2025 '!V50 -> 1053 · Accounts Receivables | C50: ='Initial TB Submitted to Auditor'!C50 -> -2.6638798e+08 | D50: -9.4894188e+08 | E50: =D50-C50 -> -6.825539e+08 | F50: MAIIC Interest Receivable net of Impairment
B51: ='TB December 2025 '!V51 -> 1054 · Mega Farms-Fertilizers-Loan | C51: ='Initial TB Submitted to Auditor'!C51 -> -3.3189976e+10 | D51: -3.3189976e+10 | E51: =D51-C51 -> 0
B52: ='TB December 2025 '!V52 -> 1055 · Mega Farms-Seed Loans | C52: ='Initial TB Submitted to Auditor'!C52 -> -7.5941669e+09 | D52: -7.5941669e+09 | E52: =D52-C52 -> 0
B53: ='TB December 2025 '!V53 -> 1056 · Mega Farms-Working Capital Loan | C53: ='Initial TB Submitted to Auditor'!C53 -> -6.6623228e+08 | D53: -6.6623228e+08 | E53: =D53-C53 -> 0
B54: ='TB December 2025 '!V54 -> 1057 · Mega Farms-Equipment Loan | C54: ='Initial TB Submitted to Auditor'!C54 -> -1.803483e+09 | D54: -1.803483e+09 | E54: =D54-C54 -> 0
B55: ='TB December 2025 '!V55 -> 1058 · Mega Farms-Irrigation Loan | C55: ='Initial TB Submitted to Auditor'!C55 -> -1.9758676e+09 | D55: -1.9758676e+09 | E55: =D55-C55 -> 0
B56: ='TB December 2025 '!V56 -> 1059 · Mega Farm Loans Interest-Capex | C56: ='Initial TB Submitted to Auditor'!C56 -> -2.1151775e+08 | D56: 2269530.6 | E56: =D56-C56 -> 2.1378728e+08 | F56: Transfer of MAIIC Interest to Receivables
B57: ='TB December 2025 '!V57 -> 1060 · Mega Farm Loans Interest-Fertil | C57: ='Initial TB Submitted to Auditor'!C57 -> -5.153939e+09 | D57: -3.1419031e+09 | E57: =D57-C57 -> 2.0120359e+09 | F57: Transfer of MAIIC Interest to Receivables
B58: ='TB December 2025 '!V58 -> 1061 · Mega Farm Loans Interest-OPEX | C58: ='Initial TB Submitted to Auditor'!C58 -> -4.3648824e+08 | D58: -3.9382455e+08 | E58: =D58-C58 -> 42663694 | F58: Transfer of MAIIC Interest to Receivables
B59: ='TB December 2025 '!V59 -> 1062 · Mega Farm Loans Interest-Seed | C59: ='Initial TB Submitted to Auditor'!C59 -> -1.2029564e+09 | D59: -7.905338e+08 | E59: =D59-C59 -> 4.1242264e+08 | F59: Transfer of MAIIC Interest to Receivables
B60: ='TB December 2025 '!V60 -> 1063 · Mega Farm - Pesticides Loan | C60: ='Initial TB Submitted to Auditor'!C60 -> -1.9370391e+09 | D60: -1.9370391e+09 | E60: =D60-C60 -> 0
B61: ='TB December 2025 '!V61 -> 1066 · ECL Megafarm Loans | C61: ='Initial TB Submitted to Auditor'!C61 -> -4.3218781e+10 | D61: -4.0944381e+10 | E61: =D61-C61 -> 2.2744004e+09 | F61: ECL Adjustment
B62: ='TB December 2025 '!V62 -> 1067 · Mega Farm Loans Interest-Pestic | C62: ='Initial TB Submitted to Auditor'!C62 -> -3.0853077e+08 | D62: -2.0172964e+08 | E62: =D62-C62 -> 1.0680113e+08 | F62: Transfer of MAIIC Interest to Receivables
B63: ='TB December 2025 '!V63 -> 1051 · Employee loan and advances | C63: ='Initial TB Submitted to Auditor'!C63 -> -3.5151237e+08 | D63: -3.5151237e+08 | E63: =D63-C63 -> 0
B64: ='TB December 2025 '!V64 -> 1052 · Prepaid expenses | C64: ='Initial TB Submitted to Auditor'!C64 -> -58392454 | D64: -58392454 | E64: =D64-C64 -> 0
B65: ='TB December 2025 '!V65 -> 1070. Mega Farms Receivable- ADMARC | C65: ='Initial TB Submitted to Auditor'!C65 -> -3.1017893e+09 | D65: -2.0844024e+09 | E65: =D65-C65 -> 1.0173869e+09 | F65: Fair Value Adjustment on Maize
B66: ='TB December 2025 '!V66 -> 1071. Mega Farms Receivable- NFRA | C66: ='Initial TB Submitted to Auditor'!C66 -> -70177833 | D66: -45345677 | E66: =D66-C66 -> 24832156 | F66: Fair Value Adjustment on Maize
B67: ='TB December 2025 '!V67 -> 1074 . Mega Farm Receivable ACE Agriculture Limited | C67: ='Initial TB Submitted to Auditor'!C67 -> -4.2913496e+08 | D67: -2.8837869e+08 | E67: =D67-C67 -> 1.4075627e+08 | F67: Fair Value Adjustment on Maize
...

Sheet Initial TB Submitted to Auditor
C2: 45992
B3: ='TB December 2025 '!V3 -> 1001 · CDH Inv Bank 0050401042201 | C3: ='TB December 2025 '!W3 -> 68950246
B4: ='TB December 2025 '!V4 -> 1002 · CDH Inv Bank PIA 0050401044100 | C4: ='TB December 2025 '!W4 -> -3276701.7
B5: ='TB December 2025 '!V5 -> 1003 · FDI Project-Payments | C5: ='TB December 2025 '!W5 -> 0
B6: ='TB December 2025 '!V6 -> 1005 · FDI Project payment-USD | C6: ='TB December 2025 '!W6 -> -4.67
B7: ='TB December 2025 '!V7 -> 1006 · Petty cash | C7: ='TB December 2025 '!W7 -> -71515.78
B8: ='TB December 2025 '!V8 -> 1012 · Money Market:1008 · Alliance Capital | C8: ='TB December 2025 '!W8 -> 0
B9: ='TB December 2025 '!V9 -> 1012 · Money Market:1009 · CDHIB Fixed Deposit | C9: ='TB December 2025 '!W9 -> -1.8777713e+09
B10: ='TB December 2025 '!V10 -> 1012 · Money Market:1010 · CDHIB Call Account | C10: ='TB December 2025 '!W10 -> -33611611
B11: ='TB December 2025 '!V11 -> 1012 · Money Market:1011 · FDH Discount House | C11: ='TB December 2025 '!W11 -> -2.6970178e+09
B12: ='TB December 2025 '!V12 -> 1012 · Money Market:1013 · MyBucks | C12: ='TB December 2025 '!W12 -> 0
B13: ='TB December 2025 '!V13 -> 1012 · Money Market:1014 · Continental Asset Management | C13: ='TB December 2025 '!W13 -> -1.599258e+09
B14: ='TB December 2025 '!V14 -> 1012 · Money Market:1015 · NICO-INV1 | C14: ='TB December 2025 '!W14 -> 0
... B211: ='TB December 2025 '!V211 -> 6860 · Utilities | C211: ='TB December 2025 '!W211 -> -14188694
B213: Totals | C213: =SUM(C3:C212) -> 1.3561919e-05

Sheet TB December 2025   
C1: December 31, 25 | N1: E-BANKER EXTRACTS ENTRIES
F2: Journals Dec 2025 | G2: JN No. | H2: Final | J2: QB Short Code | K2: QuickBooks GL Code and Description | N2: Dr | O2: Cr | Q2: Cr | R2: Dr | S2: Nett | W2: 45992
B3: 1001 · CDH Inv Bank 0050401042201 | C3: =S3 -> -68950246 | H3: =E3-C3+F3 -> 68950246 | J3: =LEFT(K3,4) -> 1001 | K3: =B3 -> 1001 · CDH Inv Bank 0050401042201 | N3: =SUMIF('Final E-Banker TB Dec 2025'!$A$3:$A$192,J3,'Final E-Banker TB Dec 2025'!$G$3:$G$192) -> 0 | O3: =SUMIF('Final E-Banker TB Dec 2025'!$A$3:$A$192,'TB December 2025 '!J3,'Final E-Banker TB Dec 2025'!$H$3:$H$192) -> 68950246 | Q3: =-O3 -> -68950246 | R3: =N3 -> 0 | S3: =Q3+R3 -> -68950246 | V3: =B3 -> 1001 · CDH Inv Bank 0050401042201 | W3: =H3 -> 68950246
B4: 1002 · CDH Inv Bank PIA 0050401044100 | C4: =S4 -> 3276701.7 | H4: =E4-C4+F4 -> -3276701.7 | J4: =LEFT(K4,4) -> 1002 | K4: =B4 -> 1002 · CDH Inv Bank PIA 0050401044100 | N4: =SUMIF('Final E-Banker TB Dec 2025'!$A$3:$A$192,J4,'Final E-Banker TB Dec 2025'!$G$3:$G$192) -> 3276701.7 | O4: =SUMIF('Final E-Banker TB Dec 2025'!$A$3:$A$192,'TB December 2025 '!J4,'Final E-Banker TB Dec 2025'!$H$3:$H$192) -> 0 | Q4: =-O4 -> 0 | R4: =N4 -> 3276701.7 | S4: =Q4+R4 -> 3276701.7 | V4: =B4 -> 1002 · CDH Inv Bank PIA 0050401044100 | W4: =H4 -> -3276701.7
B5: 1003 · FDI Project-Payments | C5: =S5 -> 0 | H5: =E5-C5+F5 -> 0 | J5: =LEFT(K5,4) -> 1003 | K5: =B5 -> 1003 · FDI Project-Payments | N5: =SUMIF('Final E-Banker TB Dec 2025'!$A$3:$A$192,J5,'Final E-Banker TB Dec 2025'!$G$3:$G$192) -> 0 | O5: =SUMIF('Final E-Banker TB Dec 2025'!$A$3:$A$192,'TB December 2025 '!J5,'Final E-Banker TB Dec 2025'!$H$3:$H$192) -> 0 | Q5: =-O5 -> 0 | R5: =N5 -> 0 | S5: =Q5+R5 -> 0 | V5: =B5 -> 1003 · FDI Project-Payments | W5: =H5 -> 0
B6: 1005 · FDI Project payment-USD | C6: =S6 -> 4.67 | H6: =E6-C6+F6 -> -4.67 | J6: =LEFT(K6,4) -> 1005 | K6: =B6 -> 1005 · FDI Project payment-USD | N6: =SUMIF('Final E-Banker TB Dec 2025'!$A$3:$A$192,J6,'Final E-Banker TB Dec 2025'!$G$3:$G$192) -> 4.67 | O6: =SUMIF('Final E-Banker TB Dec 2025'!$A$3:$A$192,'TB December 2025 '!J6,'Final E-Banker TB Dec 2025'!$H$3:$H$192) -> 0 | Q6: =-O6 -> 0 | R6: =N6 -> 4.67 | S6: =Q6+R6 -> 4.67 | V6: =B6 -> 1005 · FDI Project payment-USD | W6: =H6 -> -4.67
B7: 1006 · Petty cash | C7: =S7 -> 71515.78 | H7: =E7-C7+F7 -> -71515.78 | J7: =LEFT(K7,4) -> 1006 | K7: =B7 -> 1006 · Petty cash | N7: =SUMIF('Final E-Banker TB Dec 2025'!$A$3:$A$192,J7,'Final E-Banker TB Dec 2025'!$G$3:$G$192) -> 71515.78 | O7: =SUMIF('Final E-Banker TB Dec 2025'!$A$3:$A$192,'TB December 2025 '!J7,'Final E-Banker TB Dec 2025'!$H$3:$H$192) -> 0 | Q7: =-O7 -> 0 | R7: =N7 -> 71515.78 | S7: =Q7+R7 -> 71515.78 | V7: =B7 -> 1006 · Petty cash | W7: =H7 -> -71515.78
B8: 1012 · Money Market:1008 · Alliance Capital | C8: =S8 -> 0 | H8: =E8-C8+F8 -> 0 | J8: =LEFT(K8,4) -> 1012 | K8: =B8 -> 1012 · Money Market:1008 · Alliance Capital | N8: =SUMIF('Final E-Banker TB Dec 2025'!$A$3:$A$192,J8,'Final E-Banker TB Dec 2025'!$G$3:$G$192) -> 0 | O8: =SUMIF('Final E-Banker TB Dec 2025'!$A$3:$A$192,'TB December 2025 '!J8,'Final E-Banker TB Dec 2025'!$H$3:$H$192) -> 0 | Q8: =-O8 -> 0 | R8: =N8 -> 0 | S8: =Q8+R8 -> 0 | V8: =B8 -> 1012 · Money Market:1008 · Alliance Capital | W8: =H8 -> 0
B9: 1012 · Money Market:1009 · CDHIB Fixed Deposit | C9: =S9 -> 1.8777713e+09 | H9: =E9-C9+F9 -> -1.8777713e+09 | J9: =LEFT(K9,4) -> 1012 | K9: =B9 -> 1012 · Money Market:1009 · CDHIB Fixed Deposit | N9: ='Final E-Banker TB Dec 2025'!G13 -> 1.8777713e+09 | O9: =SUMIF('Final E-Banker TB Dec 2025'!$A$3:$A$192,'TB December 2025 '!J9,'Final E-Banker TB Dec 2025'!$H$3:$H$192) -> 0 | Q9: =-O9 -> 0 | R9: =N9 -> 1.8777713e+09 | S9: =Q9+R9 -> 1.8777713e+09 | V9: =B9 -> 1012 · Money Market:1009 · CDHIB Fixed Deposit | W9: =H9 -> -1.8777713e+09
B10: 1012 · Money Market:1010 · CDHIB Call Account | C10: =S10 -> 33611611 | H10: =E10-C10+F10 -> -33611611 | J10: =LEFT(K10,4) -> 1012 | K10: =B10 -> 1012 · Money Market:1010 · CDHIB Call Account | N10: ='Final E-Banker TB Dec 2025'!G9 -> 33611611 | O10: =SUMIF('Final E-Banker TB Dec 2025'!$A$3:$A$192,'TB December 2025 '!J10,'Final E-Banker TB Dec 2025'!$H$3:$H$192) -> 0 | Q10: =-O10 -> 0 | R10: =N10 -> 33611611 | S10: =Q10+R10 -> 33611611 | V10: =B10 -> 1012 · Money Market:1010 · CDHIB Call Account | W10: =H10 -> -33611611
B11: 1012 · Money Market:1011 · FDH Discount House | C11: =S11 -> 2.6970178e+09 | H11: =E11-C11+F11 -> -2.6970178e+09 | J11: =LEFT(K11,4) -> 1012 | K11: =B11 -> 1012 · Money Market:1011 · FDH Discount House | N11: ='Final E-Banker TB Dec 2025'!G10 -> 2.6970178e+09 | O11: =SUMIF('Final E-Banker TB Dec 2025'!$A$3:$A$192,'TB December 2025 '!J11,'Final E-Banker TB Dec 2025'!$H$3:$H$192) -> 0 | Q11: =-O11 -> 0 | R11: =N11 -> 2.6970178e+09 | S11: =Q11+R11 -> 2.6970178e+09 | V11: =B11 -> 1012 · Money Market:1011 · FDH Discount House | W11: =H11 -> -2.6970178e+09
B12: 1012 · Money Market:1013 · MyBucks | C12: =S12 -> 0 | H12: =E12-C12+F12 -> 0 | J12: =LEFT(K12,4) -> 1012 | K12: =B12 -> 1012 · Money Market:1013 · MyBucks | N12: =SUMIF('Final E-Banker TB Dec 2025'!$A$3:$A$192,J12,'Final E-Banker TB Dec 2025'!$G$3:$G$192) -> 0 | O12: =SUMIF('Final E-Banker TB Dec 2025'!$A$3:$A$192,'TB December 2025 '!J12,'Final E-Banker TB Dec 2025'!$H$3:$H$192) -> 0 | Q12: =-O12 -> 0 | R12: =N12 -> 0 | S12: =Q12+R12 -> 0 | V12: =B12 -> 1012 · Money Market:1013 · MyBucks | W12: =H12 -> 0
B13: 1012 · Money Market:1014 · Continental Asset Management | C13: =S13 -> 1.599258e+09 | H13: =E13-C13+F13 -> -1.599258e+09 | J13: 1014 | K13: =B13 -> 1012 · Money Market:1014 · Continental Asset Management | N13: =SUMIF('Final E-Banker TB Dec 2025'!$A$3:$A$192,J13,'Final E-Banker TB Dec 2025'!$G$3:$G$192) -> 1.599258e+09 | O13: =SUMIF('Final E-Banker TB Dec 2025'!$A$3:$A$192,'TB December 2025 '!J13,'Final E-Banker TB Dec 2025'!$H$3:$H$192) -> 0 | Q13: =-O13 -> 0 | R13: =N13 -> 1.599258e+09 | S13: =Q13+R13 -> 1.599258e+09 | V13: =B13 -> 1012 · Money Market:1014 · Continental Asset Management | W13: =H13 -> -1.599258e+09
B14: 1012 · Money Market:1015 · NICO-INV1 | C14: =S14 -> 0 | H14: =E14-C14+F14 -> 0 | J14: =LEFT(K14,4) -> 1012 | K14: =B14 -> 1012 · Money Market:1015 · NICO-INV1 | N14: =SUMIF('Final E-Banker TB Dec 2025'!$A$3:$A$192,J14,'Final E-Banker TB Dec 2025'!$G$3:$G$192) -> 0 | O14: =SUMIF('Final E-Banker TB Dec 2025'!$A$3:$A$192,'TB December 2025 '!J14,'Final E-Banker TB Dec 2025'!$H$3:$H$192) -> 0 | Q14: =-O14 -> 0 | R14: =N14 -> 0 | S14: =Q14+R14 -> 0 | V14: =B14 -> 1012 · Money Market:1015 · NICO-INV1 | W14: =H14 -> 0
B15: 1012 · Money Market:1016 · Treasury Note | C15: =S15 -> 0 | H15: =E15-C15+F15 -> 0 | J15: =LEFT(K15,4) -> 1012 | K15: =B15 -> 1012 · Money Market:1016 · Treasury Note | N15: =SUMIF('Final E-Banker TB Dec 2025'!$A$3:$A$192,J15,'Final E-Banker TB Dec 2025'!$G$3:$G$192) -> 0 | O15: =SUMIF('Final E-Banker TB Dec 2025'!$A$3:$A$192,'TB December 2025 '!J15,'Final E-Banker TB Dec 2025'!$H$3:$H$192) -> 0 | Q15: =-O15 -> 0 | R15: =N15 -> 0 | S15: =Q15+R15 -> 0 | V15: =B15 -> 1012 · Money Market:1016 · Treasury Note | W15: =H15 -> 0
B16: 1012 · Money Market:1020 · FINCA | C16: =S16 -> 0 | H16: =E16-C16+F16 -> 0 | J16: =LEFT(K16,4) -> 1012 | K16: =B16 -> 1012 · Money Market:1020 · FINCA | N16: =SUMIF('Final E-Banker TB Dec 2025'!$A$3:$A$192,J16,'Final E-Banker TB Dec 2025'!$G$3:$G$192) -> 0 | O16: =SUMIF('Final E-Banker TB Dec 2025'!$A$3:$A$192,'TB December 2025 '!J16,'Final E-Banker TB Dec 2025'!$H$3:$H$192) -> 0 | Q16: =-O16 -> 0 | R16: =N16 -> 0 | S16: =Q16+R16 -> 0 | V16: =B16 -> 1012 · Money Market:1020 · FINCA | W16: =H16 -> 0
B17: 1012 · Money Market:1025 · CDHIB Fixed Deposit (USD) | C17: =S17 -> 2.9358364e+08 | H17: =E17-C17+F17 -> -2.9358364e+08 | J17: 1025 | K17: =B17 -> 1012 · Money Market:1025 · CDHIB Fixed Deposit (USD) | N17: =SUMIF('Final E-Banker TB Dec 2025'!$A$3:$A$192,J17,'Final E-Banker TB Dec 2025'!$G$3:$G$192) -> 2.9358364e+08 | O17: =SUMIF('Final E-Banker TB Dec 2025'!$A$3:$A$192,'TB December 2025 '!J17,'Final E-Banker TB Dec 2025'!$H$3:$H$192) -> 0 | Q17: =-O17 -> 0 | R17: =N17 -> 2.9358364e+08 | S17: =Q17+R17 -> 2.9358364e+08 | V17: =B17 -> 1012 · Money Market:1025 · CDHIB Fixed Deposit (USD) | W17: =H17 -> -2.9358364e+08
B18: 1012 · Money Market:1026 · NICO-INV 2 | C18: =S18 -> 0 | H18: =E18-C18+F18 -> 0 | J18: =LEFT(K18,4) -> 1012 | K18: =B18 -> 1012 · Money Market:1026 · NICO-INV 2 | N18: =SUMIF('Final E-Banker TB Dec 2025'!$A$3:$A$192,J18,'Final E-Banker TB Dec 2025'!$G$3:$G$192) -> 0 | O18: =SUMIF('Final E-Banker TB Dec 2025'!$A$3:$A$192,'TB December 2025 '!J18,'Final E-Banker TB Dec 2025'!$H$3:$H$192) -> 0 | Q18: =-O18 -> 0 | R18: =N18 -> 0 | S18: =Q18+R18 -> 0 | V18: =B18 -> 1012 · Money Market:1026 · NICO-INV 2 | W18: =H18 -> 0
B19: 1012 · Money Market:1027 · CDHIB Call Account FInES | C19: =S19 -> 36229353 | H19: =E19-C19+F19 -> -36229353 | J19: 1027 | K19: =B19 -> 1012 · Money Market:1027 · CDHIB Call Account FInES | N19: =SUMIF('Final E-Banker TB Dec 2025'!$A$3:$A$192,J19,'Final E-Banker TB Dec 2025'!$G$3:$G$192) -> 36229353 | O19: =SUMIF('Final E-Banker TB Dec 2025'!$A$3:$A$192,'TB December 2025 '!J19,'Final E-Banker TB Dec 2025'!$H$3:$H$192) -> 0 | Q19: =-O19 -> 0 | R19: =N19 -> 36229353 | S19: =Q19+R19 -> 36229353 | V19: =B19 -> 1012 · Money Market:1027 · CDHIB Call Account FInES | W19: =H19 -> -36229353
B20: 1012 · Money Market:1028 · Old Mutual Investment Group Ltd | C20: =S20 -> 0.18 | H20: =E20-C20+F20 -> -0.18 | J20: 1028 | K20: =B20 -> 1012 · Money Market:1028 · Old Mutual Investment Group Ltd | N20: =SUMIF('Final E-Banker TB Dec 2025'!$A$3:$A$192,J20,'Final E-Banker TB Dec 2025'!$G$3:$G$192) -> 0.18 | O20: =SUMIF('Final E-Banker TB Dec 2025'!$A$3:$A$192,'TB December 2025 '!J20,'Final E-Banker TB Dec 2025'!$H$3:$H$192) -> 0 | Q20: =-O20 -> 0 | R20: =N20 -> 0.18 | S20: =Q20+R20 -> 0.18 | V20: =B20 -> 1012 · Money Market:1028 · Old Mutual Investment Group Ltd | W20: =H20 -> -0.18
B21: 1012 · Money Market:1031 · CDHIB Fixed Deposit (USD) 2 | C21: =S21 -> 3.6123281e+08 | H21: =E21-C21+F21 -> -3.6123281e+08 | J21: 1031 | K21: =B21 -> 1012 · Money Market:1031 · CDHIB Fixed Deposit (USD) 2 | N21: =SUMIF('Final E-Banker TB Dec 2025'!$A$3:$A$192,J21,'Final E-Banker TB Dec 2025'!$G$3:$G$192) -> 3.6123281e+08 | O21: =SUMIF('Final E-Banker TB Dec 2025'!$A$3:$A$192,'TB December 2025 '!J21,'Final E-Banker TB Dec 2025'!$H$3:$H$192) -> 0 | Q21: =-O21 -> 0 | R21: =N21 -> 3.6123281e+08 | S21: =Q21+R21 -> 3.6123281e+08 | V21: =B21 -> 1012 · Money Market:1031 · CDHIB Fixed Deposit (USD) 2 | W21: =H21 -> -3.6123281e+08
B22: 1012 · Money Market:1032 · CDHIB Fixed Deposit (USD) 3 | C22: =S22 -> 44302226 | H22: =E22-C22+F22 -> -44302226 | J22: 1032 | K22: =B22 -> 1012 · Money Market:1032 · CDHIB Fixed Deposit (USD) 3 | N22: =SUMIF('Final E-Banker TB Dec 2025'!$A$3:$A$192,J22,'Final E-Banker TB Dec 2025'!$G$3:$G$192) -> 44302226 | O22: =SUMIF('Final E-Banker TB Dec 2025'!$A$3:$A$192,'TB December 2025 '!J22,'Final E-Banker TB Dec 2025'!$H$3:$H$192) -> 0 | Q22: =-O22 -> 0 | R22: =N22 -> 44302226 | S22: =Q22+R22 -> 44302226 | V22: =B22 -> 1012 · Money Market:1032 · CDHIB Fixed Deposit (USD) 3 | W22: =H22 -> -44302226
B23: 1012 · Money Market:1033 · NBS Bank- Mega Farms 1 | C23: =S23 -> 0 | H23: =E23-C23+F23 -> 0 | J23: =LEFT(K23,4) -> 1012 | K23: =B23 -> 1012 · Money Market:1033 · NBS Bank- Mega Farms 1 | N23: =SUMIF('Final E-Banker TB Dec 2025'!$A$3:$A$192,J23,'Final E-Banker TB Dec 2025'!$G$3:$G$192) -> 0 | O23: =SUMIF('Final E-Banker TB Dec 2025'!$A$3:$A$192,'TB December 2025 '!J23,'Final E-Banker TB Dec 2025'!$H$3:$H$192) -> 0 | Q23: =-O23 -> 0 | R23: =N23 -> 0 | S23: =Q23+R23 -> 0 | V23: =B23 -> 1012 · Money Market:1033 · NBS Bank- Mega Farms 1 | W23: =H23 -> 0
B24: 1012 · Money Market:1034 · NBS Bank Mega Farms 2 | C24: =S24 -> 0 | H24: =E24-C24+F24 -> 0 | J24: =LEFT(K24,4) -> 1012 | K24: =B24 -> 1012 · Money Market:1034 · NBS Bank Mega Farms 2 | N24: =SUMIF('Final E-Banker TB Dec 2025'!$A$3:$A$192,J24,'Final E-Banker TB Dec 2025'!$G$3:$G$192) -> 0 | O24: =SUMIF('Final E-Banker TB Dec 2025'!$A$3:$A$192,'TB December 2025 '!J24,'Final E-Banker TB Dec 2025'!$H$3:$H$192) -> 0 | Q24: =-O24 -> 0 | R24: =N24 -> 0 | S24: =Q24+R24 -> 0 | V24: =B24 -> 1012 · Money Market:1034 · NBS Bank Mega Farms 2 | W24: =H24 -> 0
B25: 1012 · Money Market:1035 · Continental Asset Management 2 | C25: =S25 -> 6.4545771e+09 | H25: =E25-C25+F25 -> -6.4545771e+09 | J25: 1035 | K25: =B25 -> 1012 · Money Market:1035 · Continental Asset Management 2 | N25: =SUMIF('Final E-Banker TB Dec 2025'!$A$3:$A$192,J25,'Final E-Banker TB Dec 2025'!$G$3:$G$192) -> 6.4545771e+09 | O25: =SUMIF('Final E-Banker TB Dec 2025'!$A$3:$A$192,'TB December 2025 '!J25,'Final E-Banker TB Dec 2025'!$H$3:$H$192) -> 0 | Q25: =-O25 -> 0 | R25: =N25 -> 6.4545771e+09 | S25: =Q25+R25 -> 6.4545771e+09 | V25: =B25 -> 1012 · Money Market:1035 · Continental Asset Management 2 | W25: =H25 -> -6.4545771e+09
B26: 1012 · Money Market:1037 · CDHIB Call Account AGCOM | C26: =S26 -> 29851626 | H26: =E26-C26+F26 -> -29851626 | J26: 1037 | K26: =B26 -> 1012 · Money Market:1037 · CDHIB Call Account AGCOM | N26: =SUMIF('Final E-Banker TB Dec 2025'!$A$3:$A$192,J26,'Final E-Banker TB Dec 2025'!$G$3:$G$192) -> 29851626 | O26: =SUMIF('Final E-Banker TB Dec 2025'!$A$3:$A$192,'TB December 2025 '!J26,'Final E-Banker TB Dec 2025'!$H$3:$H$192) -> 0 | Q26: =-O26 -> 0 | R26: =N26 -> 29851626 | S26: =Q26+R26 -> 29851626 | V26: =B26 -> 1012 · Money Market:1037 · CDHIB Call Account AGCOM | W26: =H26 -> -29851626
B27: 1012 · Money Market:1038 · CDHIB Fixed Deposit AGCOM | C27: =S27 -> 1808285074 | H27: =E27-C27+F27 -> -1808285074 | J27: 1038 | K27: =B27 -> 1012 · Money Market:1038 · CDHIB Fixed Deposit AGCOM | N27: =SUMIF('Final E-Banker TB Dec 2025'!$A$3:$A$192,J27,'Final E-Banker TB Dec 2025'!$G$3:$G$192) -> 1808285074 | O27: =SUMIF('Final E-Banker TB Dec 2025'!$A$3:$A$192,'TB December 2025 '!J27,'Final E-Banker TB Dec 2025'!$H$3:$H$192) -> 0 | Q27: =-O27 -> 0 | R27: =N27 -> 1808285074 | S27: =Q27+R27 -> 1808285074 | V27: =B27 -> 1012 · Money Market:1038 · CDHIB Fixed Deposit AGCOM | W27: =H27 -> -1808285074
B28: 1012 · Money Market:1043 · NBS Money Market | C28: =S28 -> 0 | H28: =E28-C28+F28 -> 0 | J28: =LEFT(K28,4) -> 1012 | K28: =B28 -> 1012 · Money Market:1043 · NBS Money Market | N28: =SUMIF('Final E-Banker TB Dec 2025'!$A$3:$A$192,J28,'Final E-Banker TB Dec 2025'!$G$3:$G$192) -> 0 | O28: =SUMIF('Final E-Banker TB Dec 2025'!$A$3:$A$192,'TB December 2025 '!J28,'Final E-Banker TB Dec 2025'!$H$3:$H$192) -> 0 | Q28: =-O28 -> 0 | R28: =N28 -> 0 | S28: =Q28+R28 -> 0 | V28: =B28 -> 1012 · Money Market:1043 · NBS Money Market | W28: =H28 -> 0
B29: 1012 · Money Market:1044 · FDH Discount House 2 | C29: =S29 -> 2.0169857e+09 | H29: =E29-C29+F29 -> -2.0169857e+09 | J29: 1044 | K29: =B29 -> 1012 · Money Market:1044 · FDH Discount House 2 | N29: =SUMIF('Final E-Banker TB Dec 2025'!$A$3:$A$192,J29,'Final E-Banker TB Dec 2025'!$G$3:$G$192) -> 2.0169857e+09 | O29: =SUMIF('Final E-Banker TB Dec 2025'!$A$3:$A$192,'TB December 2025 '!J29,'Final E-Banker TB Dec 2025'!$H$3:$H$192) -> 0 | Q29: =-O29 -> 0 | R29: =N29 -> 2.0169857e+09 | S29: =Q29+R29 -> 2.0169857e+09 | V29: =B29 -> 1012 · Money Market:1044 · FDH Discount House 2 | W29: =H29 -> -2.0169857e+09
B30: 1012 · Money Market:1045 · FDH Discount House 3 | C30: =S30 -> 0 | H30: =E30-C30+F30 -> 0 | J30: =LEFT(K30,4) -> 1012 | K30: =B30 -> 1012 · Money Market:1045 · FDH Discount House 3 | N30: =SUMIF('Final E-Banker TB Dec 2025'!$A$3:$A$192,J30,'Final E-Banker TB Dec 2025'!$G$3:$G$192) -> 0 | O30: =SUMIF('Final E-Banker TB Dec 2025'!$A$3:$A$192,'TB December 2025 '!J30,'Final E-Banker TB Dec 2025'!$H$3:$H$192) -> 0 | Q30: =-O30 -> 0 | R30: =N30 -> 0 | S30: =Q30+R30 -> 0 | V30: =B30 -> 1012 · Money Market:1045 · FDH Discount House 3 | W30: =H30 -> 0
B31: 1012 · Money Market:1047 · NICO Asset Managers | C31: =S31 -> 3.8223606e+09 | H31: =E31-C31+F31 -> -3.8223606e+09 | J31: 1047 | K31: =B31 -> 1012 · Money Market:1047 · NICO Asset Managers | N31: =SUMIF('Final E-Banker TB Dec 2025'!$A$3:$A$192,J31,'Final E-Banker TB Dec 2025'!$G$3:$G$192) -> 3.8223606e+09 | O31: =SUMIF('Final E-Banker TB Dec 2025'!$A$3:$A$192,'TB December 2025 '!J31,'Final E-Banker TB Dec 2025'!$H$3:$H$192) -> 0 | Q31: =-O31 -> 0 | R31: =N31 -> 3.8223606e+09 | S31: =Q31+R31 -> 3.8223606e+09 | V31: =B31 -> 1012 · Money Market:1047 · NICO Asset Managers | W31: =H31 -> -3.8223606e+09
B32: 1017 · NBS Cash collection | C32: =S32 -> 3.3951404e+08 | H32: =E32-C32+F32 -> -3.3951404e+08 | J32: =LEFT(K32,4) -> 1017 | K32: =B32 -> 1017 · NBS Cash collection | N32: =SUMIF('Final E-Banker TB Dec 2025'!$A$3:$A$192,J32,'Final E-Banker TB Dec 2025'!$G$3:$G$192) -> 3.3951404e+08 | O32: =SUMIF('Final E-Banker TB Dec 2025'!$A$3:$A$192,'TB December 2025 '!J32,'Final E-Banker TB Dec 2025'!$H$3:$H$192) -> 0 | Q32: =-O32 -> 0 | R32: =N32 -> 3.3951404e+08 | S32: =Q32+R32 -> 3.3951404e+08 | V32: =B32 -> 1017 · NBS Cash collection | W32: =H32 -> -3.3951404e+08
B33: 1018 · NBS Current A/C 21011223 | C33: =S33 -> 1.93082e+08 | H33: =E33-C33+F33 -> -1.93082e+08 | J33: =LEFT(K33,4) -> 1018 | K33: =B33 -> 1018 · NBS Current A/C 21011223 | N33: =SUMIF('Final E-Banker TB Dec 2025'!$A$3:$A$192,J33,'Final E-Banker TB Dec 2025'!$G$3:$G$192) -> 1.93082e+08 | O33: =SUMIF('Final E-Banker TB Dec 2025'!$A$3:$A$192,'TB December 2025 '!J33,'Final E-Banker TB Dec 2025'!$H$3:$H$192) -> 0 | Q33: =-O33 -> 0 | R33: =N33 -> 1.93082e+08 | S33: =Q33+R33 -> 1.93082e+08 | V33: =B33 -> 1018 · NBS Current A/C 21011223 | W33: =H33 -> -1.93082e+08
B34: 1019 · NBS USD A/C 21011436 | C34: =S34 -> 1846377.7 | H34: =E34-C34+F34 -> -1846377.7 | J34: =LEFT(K34,4) -> 1019 | K34: =B34 -> 1019 · NBS USD A/C 21011436 | N34: =SUMIF('Final E-Banker TB Dec 2025'!$A$3:$A$192,J34,'Final E-Banker TB Dec 2025'!$G$3:$G$192) -> 1846377.7 | O34: =SUMIF('Final E-Banker TB Dec 2025'!$A$3:$A$192,'TB December 2025 '!J34,'Final E-Banker TB Dec 2025'!$H$3:$H$192) -> 0 | Q34: =-O34 -> 0 | R34: =N34 -> 1846377.7 | S34: =Q34+R34 -> 1846377.7 | V34: =B34 -> 1019 · NBS USD A/C 21011436 | W34: =H34 -> -1846377.7
B35: 1021 · NBS Money Market | C35: =S35 -> 1.5152771e+09 | H35: =E35-C35+F35 -> -1.5152771e+09 | J35: =LEFT(K35,4) -> 1021 | K35: =B35 -> 1021 · NBS Money Market | N35: =SUMIF('Final E-Banker TB Dec 2025'!$A$3:$A$192,J35,'Final E-Banker TB Dec 2025'!$G$3:$G$192) -> 1.5152771e+09 | O35: =SUMIF('Final E-Banker TB Dec 2025'!$A$3:$A$192,'TB December 2025 '!J35,'Final E-Banker TB Dec 2025'!$H$3:$H$192) -> 0 | Q35: =-O35 -> 0 | R35: =N35 -> 1.5152771e+09 | S35: =Q35+R35 -> 1.5152771e+09 | V35: =B35 -> 1021 · NBS Money Market | W35: =H35 -> -1.5152771e+09
B36: 1022 · AGRA- FCDA | C36: =S36 -> 2.7874847e+08 | H36: =E36-C36+F36 -> -2.7874847e+08 | J36: =LEFT(K36,4) -> 1022 | K36: =B36 -> 1022 · AGRA- FCDA | N36: =SUMIF('Final E-Banker TB Dec 2025'!$A$3:$A$192,J36,'Final E-Banker TB Dec 2025'!$G$3:$G$192) -> 2.7874847e+08 | O36: =SUMIF('Final E-Banker TB Dec 2025'!$A$3:$A$192,'TB December 2025 '!J36,'Final E-Banker TB Dec 2025'!$H$3:$H$192) -> 0 | Q36: =-O36 -> 0 | R36: =N36 -> 2.7874847e+08 | S36: =Q36+R36 -> 2.7874847e+08 | V36: =B36 -> 1022 · AGRA- FCDA | W36: =H36 -> -2.7874847e+08
B37: 1023 · MICF- Mbora FCDA | C37: =S37 -> 5.46 | H37: =E37-C37+F37 -> -5.46 | J37: =LEFT(K37,4) -> 1023 | K37: =B37 -> 1023 · MICF- Mbora FCDA | N37: =SUMIF('Final E-Banker TB Dec 2025'!$A$3:$A$192,J37,'Final E-Banker TB Dec 2025'!$G$3:$G$192) -> 5.46 | O37: =SUMIF('Final E-Banker TB Dec 2025'!$A$3:$A$192,'TB December 2025 '!J37,'Final E-Banker TB Dec 2025'!$H$3:$H$192) -> 0 | Q37: =-O37 -> 0 | R37: =N37 -> 5.46 | S37: =Q37+R37 -> 5.46 | V37: =B37 -> 1023 · MICF- Mbora FCDA | W37: =H37 -> -5.46
B38: 1024 · RBM - Treasury Bills | C38: =S38 -> 0 | H38: =E38-C38+F38 -> 0 | J38: =LEFT(K38,4) -> 1024 | K38: =B38 -> 1024 · RBM - Treasury Bills | N38: =SUMIF('Final E-Banker TB Dec 2025'!$A$3:$A$192,J38,'Final E-Banker TB Dec 2025'!$G$3:$G$192) -> 0 | O38: =SUMIF('Final E-Banker TB Dec 2025'!$A$3:$A$192,'TB December 2025 '!J38,'Final E-Banker TB Dec 2025'!$H$3:$H$192) -> 0 | Q38: =-O38 -> 0 | R38: =N38 -> 0 | S38: =Q38+R38 -> 0 | V38: =B38 -> 1024 · RBM - Treasury Bills | W38: =H38 -> 0
B39: 1029 · NBS Money Market Acc 2 | C39: =S39 -> 8.0886178e+08 | H39: =E39-C39+F39 -> -8.0886178e+08 | J39: =LEFT(K39,4) -> 1029 | K39: =B39 -> 1029 · NBS Money Market Acc 2 | N39: =SUMIF('Final E-Banker TB Dec 2025'!$A$3:$A$192,J39,'Final E-Banker TB Dec 2025'!$G$3:$G$192) -> 8.0886178e+08 | O39: =SUMIF('Final E-Banker TB Dec 2025'!$A$3:$A$192,'TB December 2025 '!J39,'Final E-Banker TB Dec 2025'!$H$3:$H$192) -> 0 | Q39: =-O39 -> 0 | R39: =N39 -> 8.0886178e+08 | S39: =Q39+R39 -> 8.0886178e+08 | V39: =B39 -> 1029 · NBS Money Market Acc 2 | W39: =H39 -> -8.0886178e+08
B40: 1036 · NBS Bank Mega Farms | C40: =S40 -> 0 | H40: =E40-C40+F40 -> 0 | J40: =LEFT(K40,4) -> 1036 | K40: =B40 -> 1036 · NBS Bank Mega Farms | N40: =SUMIF('Final E-Banker TB Dec 2025'!$A$3:$A$192,J40,'Final E-Banker TB Dec 2025'!$G$3:$G$192) -> 0 | O40: =SUMIF('Final E-Banker TB Dec 2025'!$A$3:$A$192,'TB December 2025 '!J40,'Final E-Banker TB Dec 2025'!$H$3:$H$192) -> 0 | Q40: =-O40 -> 0 | R40: =N40 -> 0 | S40: =Q40+R40 -> 0 | V40: =B40 -> 1036 · NBS Bank Mega Farms | W40: =H40 -> 0
...

Sheet Final E-Banker TB Dec 2025
B2: GL Title | C2: Debit | D2: Credit | G2: Dr | H2: Cr
A3: =LEFT(B3,4) -> 1017 | B3: 1017...NBS Cash Collection | C3: 3.3951404e+08 | D3: 0.00 | G3: =C3*1 -> 3.3951404e+08 | H3: =D3*1 -> 0
A4: =LEFT(B4,4) -> 1018 | B4: 1018...NBS Current A/C 21011223 | C4: 1.93082e+08 | D4: 0.00 | G4: =C4*1 -> 1.93082e+08 | H4: =D4*1 -> 0
A5: =LEFT(B5,4) -> 1046 | B5: 1046...First Capital Bank | C5: 28486995 | D5: 0.00 | G5: =C5*1 -> 28486995 | H5: =D5*1 -> 0
A6: =LEFT(B6,4) -> 1001 | B6: 1001...CDH Inv Bank 0050401042201 | C6: 0.00 | D6: 68950246 | G6: =C6*1 -> 0 | H6: =D6*1 -> 68950246
A7: =LEFT(B7,4) -> 1048 | B7: 1048...CDH MAIIC AGRA (MK) | C7: 36188936 | D7: 0.00 | G7: =C7*1 -> 36188936 | H7: =D7*1 -> 0
A8: =LEFT(B8,4) -> 1022 | B8: 1022...AGRA- FCDA | C8: 2.7874847e+08 | D8: 0.00 | G8: =C8*1 -> 2.7874847e+08 | H8: =D8*1 -> 0
A9: =LEFT(B9,4) -> 1010 | B9: 1010...Money Market CDHIB Call Account | C9: 33611611 | D9: 0.00 | G9: =C9*1 -> 33611611 | H9: =D9*1 -> 0
A10: =LEFT(B10,4) -> 1011 | B10: 1011...Money Market FDH Discount House | C10: 2.6970178e+09 | D10: 0.00 | G10: =C10*1 -> 2.6970178e+09 | H10: =D10*1 -> 0
A11: =LEFT(B11,4) -> 1002 | B11: 1002...CDH Inv Bank PIA 0050401044100 | C11: 3276701.7 | D11: 0.00 | G11: =C11*1 -> 3276701.7 | H11: =D11*1 -> 0
A12: =LEFT(B12,4) -> 1005 | B12: 1005...FDI Project Payment-USD | C12: 4.67 | D12: 0.00 | G12: =C12*1 -> 4.67 | H12: =D12*1 -> 0
A13: =LEFT(B13,4) -> 1009 | B13: 1009...Money Market CDHIB Fixed Deposit | C13: 1.8777713e+09 | D13: 0.00 | G13: =C13*1 -> 1.8777713e+09 | H13: =D13*1 -> 0
A14: =LEFT(B14,4) -> 1014 | B14: 1014...Money Market Continental Asset Management | C14: 1.599258e+09 | D14: 0.00 | G14: =C14*1 -> 1.599258e+09 | H14: =D14*1 -> 0
A15: =LEFT(B15,4) -> 1019 | B15: 1019...NBS USD A/C 21011436 | C15: 1846377.7 | D15: 0.00 | G15: =C15*1 -> 1846377.7 | H15: =D15*1 -> 0
A16: =LEFT(B16,4) -> 1021 | B16: 1021...NBS Money Market | C16: 1.5152771e+09 | D16: 0.00 | G16: =C16*1 -> 1.5152771e+09 | H16: =D16*1 -> 0
A17: =LEFT(B17,4) -> 1023 | B17: 1023...MICF- Mbora FCDA - USD | C17: 5.46 | D17: 0.00 | G17: =C17*1 -> 5.46 | H17: =D17*1 -> 0
A18: =LEFT(B18,4) -> 1025 | B18: 1025...Money Market CDHIB Fixed Deposit (USD) | C18: 2.9358364e+08 | D18: 0.00 | G18: =C18*1 -> 2.9358364e+08 | H18: =D18*1 -> 0
A19: =LEFT(B19,4) -> 1027 | B19: 1027...Money Market CDHIB Call Account Fines | C19: 36229353 | D19: 0.00 | G19: =C19*1 -> 36229353 | H19: =D19*1 -> 0
A20: =LEFT(B20,4) -> 1031 | B20: 1031...Money Market CDHIB Fixed Deposit (USD) 2 | C20: 3.6123281e+08 | D20: 0.00 | G20: =C20*1 -> 3.6123281e+08 | H20: =D20*1 -> 0
A21: =LEFT(B21,4) -> 1032 | B21: 1032...Money Market CDHIB Fixed Deposit (USD) 3 | C21: 44302226 | D21: 0.00 | G21: =C21*1 -> 44302226 | H21: =D21*1 -> 0
A22: =LEFT(B22,4) -> 1029 | B22: 1029...NBS Money Market Acc 2 | C22: 8.0886178e+08 | D22: 0.00 | G22: =C22*1 -> 8.0886178e+08 | H22: =D22*1 -> 0
A23: =LEFT(B23,4) -> 1028 | B23: 1028...Money Market Old Mutual Investment Group Ltd | C23: 0.18 | D23: 0.00 | G23: =C23*1 -> 0.18 | H23: =D23*1 -> 0
A24: =LEFT(B24,4) -> 1035 | B24: 1035...Money Market Continental Asset Management 2 | C24: 6.4545771e+09 | D24: 0.00 | G24: =C24*1 -> 6.4545771e+09 | H24: =D24*1 -> 0
A25: =LEFT(B25,4) -> 1037 | B25: 1037...CDHIB Call Account AGCOM | C25: 29851626 | D25: 0.00 | G25: =C25*1 -> 29851626 | H25: =D25*1 -> 0
A26: =LEFT(B26,4) -> 1038 | B26: 1038...CDHIB Fixed Deposit AGCOM | C26: 1808285074 | D26: 0.00 | G26: =C26*1 -> 1808285074 | H26: =D26*1 -> 0
A27: =LEFT(B27,4) -> 1044 | B27: 1044...FDH Discount House 2 | C27: 2.0169857e+09 | D27: 0.00 | G27: =C27*1 -> 2.0169857e+09 | H27: =D27*1 -> 0
A28: =LEFT(B28,4) -> 1047 | B28: 1047...NICO Asset Managers | C28: 3.8223606e+09 | D28: 0.00 | G28: =C28*1 -> 3.8223606e+09 | H28: =D28*1 -> 0
A29: =LEFT(B29,4) -> 1006 | B29: 1006...Petty Cash | C29: 71515.78 | D29: 0.00 | G29: =C29*1 -> 71515.78 | H29: =D29*1 -> 0
A30: =LEFT(B30,4) -> 1050 | B30: 1050...Term Loans | C30: 0.00 | D30: 52033.5 | G30: =C30*1 -> 0 | H30: =D30*1 -> 52033.5
A31: =LEFT(B31,4) -> 1871 | B31: 1871...Undrawn Commitment-MAIIC | C31: 2.9191638e+09 | D31: 0.00 | G31: =C31*1 -> 2.9191638e+09 | H31: =D31*1 -> 0
A32: =LEFT(B32,4) -> 1872 | B32: 1872...Undrawn Commitments-Fines | C32: 39568984 | D32: 0.00 | G32: =C32*1 -> 39568984 | H32: =D32*1 -> 0
A33: =LEFT(B33,4) -> 2063 | B33: 2063...Undrawn Commitments MAIIC | C33: 0.00 | D33: 2.9191638e+09 | G33: =C33*1 -> 0 | H33: =D33*1 -> 2.9191638e+09
A34: =LEFT(B34,4) -> 1050 | B34: 1050101...MAIIC Agricultural Loans | C34: 1.3687378e+09 | D34: 0.00 | G34: =C34*1 -> 1.3687378e+09 | H34: =D34*1 -> 0
A35: =LEFT(B35,4) -> 1050 | B35: 1050102...MAIIC Industrial Loans | C35: 6.4340451e+09 | D35: 0.00 | G35: =C35*1 -> 6.4340451e+09 | H35: =D35*1 -> 0
A36: =LEFT(B36,4) -> 1050 | B36: 1050401...MAIIC Term Loan | C36: 1.8271481e+09 | D36: 0.00 | G36: =C36*1 -> 1.8271481e+09 | H36: =D36*1 -> 0
A37: =LEFT(B37,4) -> 1050 | B37: 1050201...FInES Agricultural Loans | C37: 1.4023931e+09 | D37: 0.00 | G37: =C37*1 -> 1.4023931e+09 | H37: =D37*1 -> 0
A38: =LEFT(B38,4) -> 1050 | B38: 1050202...FInES Industrial Loans | C38: 3.8082887e+09 | D38: 0.00 | G38: =C38*1 -> 3.8082887e+09 | H38: =D38*1 -> 0
A39: =LEFT(B39,7) -> 1050301 | B39: 1050301...Mega Farm Fertilizer Loans | C39: 3.3189976e+10 | D39: 0.00 | G39: =C39*1 -> 3.3189976e+10 | H39: =D39*1 -> 0
A40: =LEFT(B40,7) -> 1050302 | B40: 1050302...Mega Farm Seed Loans | C40: 7.5941669e+09 | D40: 0.00 | G40: =C40*1 -> 7.5941669e+09 | H40: =D40*1 -> 0
A41: =LEFT(B41,7) -> 1050303 | B41: 1050303...Mega Farm Working Capital Loans | C41: 6.6623228e+08 | D41: 0.00 | G41: =C41*1 -> 6.6623228e+08 | H41: =D41*1 -> 0
...
