Workbook

Sheet TOC
A1: Take-on schedules as at 31 October 2024, with the E-Banker account mapping to confirm
A2: Dupleix Institute for Tamanda Sitimawina, MAIIC · 7 October 2026 · start with 'Instructions'
A4: Sheet | B4: What it is | C4: Who it is for
A5: =HYPERLINK("#'Instructions'!A1","Instructions") | B5: Read first: what to do and how the sheets are linked | C5: Tamanda
A6: =HYPERLINK("#'Mapping'!A1","Mapping") | B6: One row per facility: the proposed account, five tests, your Y/N | C6: Tamanda, to fill in
A7: =HYPERLINK("#'Not matched'!A1","Not matched") | B7: The four facilities with no proposed account | C7: Tamanda, to fill in
A8: =HYPERLINK("#'Accounts without a block'!A1","Accounts without a block") | B8: E-Banker accounts opened before July 2024 with no facility in the workbook | C8: Tamanda, to fill in
A9: =HYPERLINK("#'Upload summary'!A1","Upload summary") | B9: The facilities laid out for loading, your terms beside the E-Banker terms | C9: Dupleix
A10: =HYPERLINK("#'Blocks'!A1","Blocks") | B10: One row per amortisation block, linked to its facility and account, with a link into the block | C10: Dupleix
A11: =HYPERLINK("#'E-Banker master'!A1","E-Banker master") | B11: The E-Banker values the lookups read (extracted 7 October 2026) | C11: Reference
A12: =HYPERLINK("#'Loan Book'!A1","Loan Book") | B12: Your sheet, unchanged | C12: Reference
A13: =HYPERLINK("#'Amortisation and Repayments'!A1","Amortisation and Repayments") | B13: Your sheet, unchanged | C13: Reference

Sheet Instructions
A1: What this workbook is
A2: Your take-on workbook of 11 September 2026, exactly as you sent it (the sheets 'Loan Book' and 'Amortisation and Repayments' are untouched), with six sheets added by Dupleix that link each facility and each amortisation block to its E-Banker account number.
A4: Why
A5: The pre-July-2024 history of each loan lives in your workbook; the history from July 2024 lives in E-Banker. To join the two for the effective interest rate, each facility in the workbook needs its E-Banker account number. We have proposed the number for 105 of the 109 facilities. We need you to confirm or correct each one. The fees charged at the start of each loan are the one thing neither your workbook nor E-Banker records against the loan, and the effective interest rate cannot be worked out without them: under IFRS 9 the fee is spread over the life of the loan as part of its yield. That is why the yellow fee columns are asked for.
A7: What to do, in order
A8: 1. Open the sheet 'Mapping'. For each row, look at the proposed account (column J), the E-Banker name beside it (column L) and the five tests (columns S to W). Put Y in column X if the account is right, or N and the correct account number in column Y. Column Z is for any comment.
A9: 2. Open the sheet 'Not matched'. Four facilities have no proposed account: give the account number, or write 'no account' if the facility was never set up in E-Banker (for example an equity holding, or a loan closed before the migration).
A10: 3. Open the sheet 'Accounts without a block'. These E-Banker accounts were opened before July 2024 but match no facility in your workbook. Say which facility each is, or 'none'.
A11: 4. Open the sheet 'Upload summary' and go to the yellow columns at the far right (AO to AT). For every facility, type the arrangement fee and the legal fees charged when the loan was first granted (in kwacha), any other fee that was a condition of the loan (for example a commitment or valuation fee), the date the fees were charged, whether they were deducted from the amount paid out (Y) or paid separately (N), and the reference of the offer letter or receipt you took the figures from. Leave a cell blank if there was no such fee; write 0 only if you know it was nil. Column AU adds them up for you.
A12: 5. Save the file and send it back. Nothing else needs to change.
A13: How the sheets are linked, so that everything can be audited
A14: Every workbook figure shown on the new sheets is a formula pointing at the cell in 'Loan Book' or 'Amortisation and Repayments' it comes from. Click any such cell and the formula bar shows the source. If you correct a figure in your sheets, the new sheets follow.
... A25: Prepared by Dupleix Institute, 7 October 2026. The scripts that built the new sheets are kept in our project folder (Build files) so the work can be re-run.

Sheet Mapping
A1: Loan Book row | B1: Loan Book # | C1: Facility name | D1: Type | E1: Value date | F1: Approved | G1: Disbursed | H1: Principal 31 Oct 2024 | I1: Carrying amount 31 Oct 2024 | J1: Proposed E-Banker account | K1: Confidence | L1: E-Banker name | M1: E-Banker opening date | N1: E-Banker sanction | O1: E-Banker take-on posting 31 Jul 2024 | P1: E-Banker balance 31 Oct 2024 | Q1: E-Banker first disbursement date | R1: E-Banker status | S1: Test 1: principal = take-on posting | T1: Test 2: carrying amount vs balance | U1: Test 3: approved = sanction | V1: Test 4: days, value date to first disbursement | W1: Test 5: name agrees (as scored) | X1: Tamanda: correct? (Y/N) | Y1: If N, correct account number | Z1: Comment
A2: 5 | B2: ='Loan Book'!D5 | C2: ='Loan Book'!E5 | D2: ='Loan Book'!F5 | E2: ='Loan Book'!G5 | F2: ='Loan Book'!L5 | G2: ='Loan Book'!M5 | H2: ='Loan Book'!O5 | I2: ='Loan Book'!R5 | J2: 000104430000001 | K2: High | L2: =IFERROR(INDEX('E-Banker master'!$B$2:$B$186,MATCH($J2,'E-Banker master'!$A$2:$A$186,0)),"") | M2: =IFERROR(INDEX('E-Banker master'!$H$2:$H$186,MATCH($J2,'E-Banker master'!$A$2:$A$186,0)),"") | N2: =IFERROR(INDEX('E-Banker master'!$I$2:$I$186,MATCH($J2,'E-Banker master'!$A$2:$A$186,0)),"") | O2: =IFERROR(INDEX('E-Banker master'!$N$2:$N$186,MATCH($J2,'E-Banker master'!$A$2:$A$186,0)),"") | P2: =IFERROR(INDEX('E-Banker master'!$P$2:$P$186,MATCH($J2,'E-Banker master'!$A$2:$A$186,0)),"") | Q2: =IFERROR(INDEX('E-Banker master'!$Q$2:$Q$186,MATCH($J2,'E-Banker master'!$A$2:$A$186,0)),"") | R2: =IFERROR(INDEX('E-Banker master'!$E$2:$E$186,MATCH($J2,'E-Banker master'!$A$2:$A$186,0)),"") | S2: =IF($J2="","",IF(O2="","No take-on posting",IF(ABS(H2-O2)<1,"Yes",IF(ABS(H2/O2-1)<0.01,"Within 1%","No")))) | T2: =IF($J2="","",IF(OR(P2="",P2=0),"No balance",IF(ABS(I2-P2)<1,"Yes",IF(ABS(I2/P2-1)<0.02,"Within 2%",IF(ABS(I2/P2-1)<0.05,"Within 5%","No"))))) | U2: =IF($J2="","",IF(N2="","",IF(ABS(F2-N2)<1,"Yes",IF(ABS(G2-N2)<1,"Disbursed = sanction","No")))) | V2: =IF(OR($J2="",Q2="",E2=""),"",ABS(E2-Q2)) | W2: Yes
A3: 6 | B3: ='Loan Book'!D6 | C3: ='Loan Book'!E6 | D3: ='Loan Book'!F6 | E3: ='Loan Book'!G6 | F3: ='Loan Book'!L6 | G3: ='Loan Book'!M6 | H3: ='Loan Book'!O6 | I3: ='Loan Book'!R6 | J3: 000104430000002 | K3: High | L3: =IFERROR(INDEX('E-Banker master'!$B$2:$B$186,MATCH($J3,'E-Banker master'!$A$2:$A$186,0)),"") | M3: =IFERROR(INDEX('E-Banker master'!$H$2:$H$186,MATCH($J3,'E-Banker master'!$A$2:$A$186,0)),"") | N3: =IFERROR(INDEX('E-Banker master'!$I$2:$I$186,MATCH($J3,'E-Banker master'!$A$2:$A$186,0)),"") | O3: =IFERROR(INDEX('E-Banker master'!$N$2:$N$186,MATCH($J3,'E-Banker master'!$A$2:$A$186,0)),"") | P3: =IFERROR(INDEX('E-Banker master'!$P$2:$P$186,MATCH($J3,'E-Banker master'!$A$2:$A$186,0)),"") | Q3: =IFERROR(INDEX('E-Banker master'!$Q$2:$Q$186,MATCH($J3,'E-Banker master'!$A$2:$A$186,0)),"") | R3: =IFERROR(INDEX('E-Banker master'!$E$2:$E$186,MATCH($J3,'E-Banker master'!$A$2:$A$186,0)),"") | S3: =IF($J3="","",IF(O3="","No take-on posting",IF(ABS(H3-O3)<1,"Yes",IF(ABS(H3/O3-1)<0.01,"Within 1%","No")))) | T3: =IF($J3="","",IF(OR(P3="",P3=0),"No balance",IF(ABS(I3-P3)<1,"Yes",IF(ABS(I3/P3-1)<0.02,"Within 2%",IF(ABS(I3/P3-1)<0.05,"Within 5%","No"))))) | U3: =IF($J3="","",IF(N3="","",IF(ABS(F3-N3)<1,"Yes",IF(ABS(G3-N3)<1,"Disbursed = sanction","No")))) | V3: =IF(OR($J3="",Q3="",E3=""),"",ABS(E3-Q3)) | W3: Yes
A4: 7 | B4: ='Loan Book'!D7 | C4: ='Loan Book'!E7 | D4: ='Loan Book'!F7 | E4: ='Loan Book'!G7 | F4: ='Loan Book'!L7 | G4: ='Loan Book'!M7 | H4: ='Loan Book'!O7 | I4: ='Loan Book'!R7 | J4: 000104420000003 | K4: High | L4: =IFERROR(INDEX('E-Banker master'!$B$2:$B$186,MATCH($J4,'E-Banker master'!$A$2:$A$186,0)),"") | M4: =IFERROR(INDEX('E-Banker master'!$H$2:$H$186,MATCH($J4,'E-Banker master'!$A$2:$A$186,0)),"") | N4: =IFERROR(INDEX('E-Banker master'!$I$2:$I$186,MATCH($J4,'E-Banker master'!$A$2:$A$186,0)),"") | O4: =IFERROR(INDEX('E-Banker master'!$N$2:$N$186,MATCH($J4,'E-Banker master'!$A$2:$A$186,0)),"") | P4: =IFERROR(INDEX('E-Banker master'!$P$2:$P$186,MATCH($J4,'E-Banker master'!$A$2:$A$186,0)),"") | Q4: =IFERROR(INDEX('E-Banker master'!$Q$2:$Q$186,MATCH($J4,'E-Banker master'!$A$2:$A$186,0)),"") | R4: =IFERROR(INDEX('E-Banker master'!$E$2:$E$186,MATCH($J4,'E-Banker master'!$A$2:$A$186,0)),"") | S4: =IF($J4="","",IF(O4="","No take-on posting",IF(ABS(H4-O4)<1,"Yes",IF(ABS(H4/O4-1)<0.01,"Within 1%","No")))) | T4: =IF($J4="","",IF(OR(P4="",P4=0),"No balance",IF(ABS(I4-P4)<1,"Yes",IF(ABS(I4/P4-1)<0.02,"Within 2%",IF(ABS(I4/P4-1)<0.05,"Within 5%","No"))))) | U4: =IF($J4="","",IF(N4="","",IF(ABS(F4-N4)<1,"Yes",IF(ABS(G4-N4)<1,"Disbursed = sanction","No")))) | V4: =IF(OR($J4="",Q4="",E4=""),"",ABS(E4-Q4)) | W4: Yes
A5: 8 | B5: ='Loan Book'!D8 | C5: ='Loan Book'!E8 | D5: ='Loan Book'!F8 | E5: ='Loan Book'!G8 | F5: ='Loan Book'!L8 | G5: ='Loan Book'!M8 | H5: ='Loan Book'!O8 | I5: ='Loan Book'!R8 | J5: 000104430000004 | K5: High | L5: =IFERROR(INDEX('E-Banker master'!$B$2:$B$186,MATCH($J5,'E-Banker master'!$A$2:$A$186,0)),"") | M5: =IFERROR(INDEX('E-Banker master'!$H$2:$H$186,MATCH($J5,'E-Banker master'!$A$2:$A$186,0)),"") | N5: =IFERROR(INDEX('E-Banker master'!$I$2:$I$186,MATCH($J5,'E-Banker master'!$A$2:$A$186,0)),"") | O5: =IFERROR(INDEX('E-Banker master'!$N$2:$N$186,MATCH($J5,'E-Banker master'!$A$2:$A$186,0)),"") | P5: =IFERROR(INDEX('E-Banker master'!$P$2:$P$186,MATCH($J5,'E-Banker master'!$A$2:$A$186,0)),"") | Q5: =IFERROR(INDEX('E-Banker master'!$Q$2:$Q$186,MATCH($J5,'E-Banker master'!$A$2:$A$186,0)),"") | R5: =IFERROR(INDEX('E-Banker master'!$E$2:$E$186,MATCH($J5,'E-Banker master'!$A$2:$A$186,0)),"") | S5: =IF($J5="","",IF(O5="","No take-on posting",IF(ABS(H5-O5)<1,"Yes",IF(ABS(H5/O5-1)<0.01,"Within 1%","No")))) | T5: =IF($J5="","",IF(OR(P5="",P5=0),"No balance",IF(ABS(I5-P5)<1,"Yes",IF(ABS(I5/P5-1)<0.02,"Within 2%",IF(ABS(I5/P5-1)<0.05,"Within 5%","No"))))) | U5: =IF($J5="","",IF(N5="","",IF(ABS(F5-N5)<1,"Yes",IF(ABS(G5-N5)<1,"Disbursed = sanction","No")))) | V5: =IF(OR($J5="",Q5="",E5=""),"",ABS(E5-Q5)) | W5: Yes
A6: 9 | B6: ='Loan Book'!D9 | C6: ='Loan Book'!E9 | D6: ='Loan Book'!F9 | E6: ='Loan Book'!G9 | F6: ='Loan Book'!L9 | G6: ='Loan Book'!M9 | H6: ='Loan Book'!O9 | I6: ='Loan Book'!R9 | J6: 000104420000005 | K6: High | L6: =IFERROR(INDEX('E-Banker master'!$B$2:$B$186,MATCH($J6,'E-Banker master'!$A$2:$A$186,0)),"") | M6: =IFERROR(INDEX('E-Banker master'!$H$2:$H$186,MATCH($J6,'E-Banker master'!$A$2:$A$186,0)),"") | N6: =IFERROR(INDEX('E-Banker master'!$I$2:$I$186,MATCH($J6,'E-Banker master'!$A$2:$A$186,0)),"") | O6: =IFERROR(INDEX('E-Banker master'!$N$2:$N$186,MATCH($J6,'E-Banker master'!$A$2:$A$186,0)),"") | P6: =IFERROR(INDEX('E-Banker master'!$P$2:$P$186,MATCH($J6,'E-Banker master'!$A$2:$A$186,0)),"") | Q6: =IFERROR(INDEX('E-Banker master'!$Q$2:$Q$186,MATCH($J6,'E-Banker master'!$A$2:$A$186,0)),"") | R6: =IFERROR(INDEX('E-Banker master'!$E$2:$E$186,MATCH($J6,'E-Banker master'!$A$2:$A$186,0)),"") | S6: =IF($J6="","",IF(O6="","No take-on posting",IF(ABS(H6-O6)<1,"Yes",IF(ABS(H6/O6-1)<0.01,"Within 1%","No")))) | T6: =IF($J6="","",IF(OR(P6="",P6=0),"No balance",IF(ABS(I6-P6)<1,"Yes",IF(ABS(I6/P6-1)<0.02,"Within 2%",IF(ABS(I6/P6-1)<0.05,"Within 5%","No"))))) | U6: =IF($J6="","",IF(N6="","",IF(ABS(F6-N6)<1,"Yes",IF(ABS(G6-N6)<1,"Disbursed = sanction","No")))) | V6: =IF(OR($J6="",Q6="",E6=""),"",ABS(E6-Q6)) | W6: Yes
A7: 10 | B7: ='Loan Book'!D10 | C7: ='Loan Book'!E10 | D7: ='Loan Book'!F10 | E7: ='Loan Book'!G10 | F7: ='Loan Book'!L10 | G7: ='Loan Book'!M10 | H7: ='Loan Book'!O10 | I7: ='Loan Book'!R10 | J7: 000104420000006 | K7: High | L7: =IFERROR(INDEX('E-Banker master'!$B$2:$B$186,MATCH($J7,'E-Banker master'!$A$2:$A$186,0)),"") | M7: =IFERROR(INDEX('E-Banker master'!$H$2:$H$186,MATCH($J7,'E-Banker master'!$A$2:$A$186,0)),"") | N7: =IFERROR(INDEX('E-Banker master'!$I$2:$I$186,MATCH($J7,'E-Banker master'!$A$2:$A$186,0)),"") | O7: =IFERROR(INDEX('E-Banker master'!$N$2:$N$186,MATCH($J7,'E-Banker master'!$A$2:$A$186,0)),"") | P7: =IFERROR(INDEX('E-Banker master'!$P$2:$P$186,MATCH($J7,'E-Banker master'!$A$2:$A$186,0)),"") | Q7: =IFERROR(INDEX('E-Banker master'!$Q$2:$Q$186,MATCH($J7,'E-Banker master'!$A$2:$A$186,0)),"") | R7: =IFERROR(INDEX('E-Banker master'!$E$2:$E$186,MATCH($J7,'E-Banker master'!$A$2:$A$186,0)),"") | S7: =IF($J7="","",IF(O7="","No take-on posting",IF(ABS(H7-O7)<1,"Yes",IF(ABS(H7/O7-1)<0.01,"Within 1%","No")))) | T7: =IF($J7="","",IF(OR(P7="",P7=0),"No balance",IF(ABS(I7-P7)<1,"Yes",IF(ABS(I7/P7-1)<0.02,"Within 2%",IF(ABS(I7/P7-1)<0.05,"Within 5%","No"))))) | U7: =IF($J7="","",IF(N7="","",IF(ABS(F7-N7)<1,"Yes",IF(ABS(G7-N7)<1,"Disbursed = sanction","No")))) | V7: =IF(OR($J7="",Q7="",E7=""),"",ABS(E7-Q7)) | W7: Yes
A8: 11 | B8: ='Loan Book'!D11 | C8: ='Loan Book'!E11 | D8: ='Loan Book'!F11 | E8: ='Loan Book'!G11 | F8: ='Loan Book'!L11 | G8: ='Loan Book'!M11 | H8: ='Loan Book'!O11 | I8: ='Loan Book'!R11 | J8: 000104420000007 | K8: High | L8: =IFERROR(INDEX('E-Banker master'!$B$2:$B$186,MATCH($J8,'E-Banker master'!$A$2:$A$186,0)),"") | M8: =IFERROR(INDEX('E-Banker master'!$H$2:$H$186,MATCH($J8,'E-Banker master'!$A$2:$A$186,0)),"") | N8: =IFERROR(INDEX('E-Banker master'!$I$2:$I$186,MATCH($J8,'E-Banker master'!$A$2:$A$186,0)),"") | O8: =IFERROR(INDEX('E-Banker master'!$N$2:$N$186,MATCH($J8,'E-Banker master'!$A$2:$A$186,0)),"") | P8: =IFERROR(INDEX('E-Banker master'!$P$2:$P$186,MATCH($J8,'E-Banker master'!$A$2:$A$186,0)),"") | Q8: =IFERROR(INDEX('E-Banker master'!$Q$2:$Q$186,MATCH($J8,'E-Banker master'!$A$2:$A$186,0)),"") | R8: =IFERROR(INDEX('E-Banker master'!$E$2:$E$186,MATCH($J8,'E-Banker master'!$A$2:$A$186,0)),"") | S8: =IF($J8="","",IF(O8="","No take-on posting",IF(ABS(H8-O8)<1,"Yes",IF(ABS(H8/O8-1)<0.01,"Within 1%","No")))) | T8: =IF($J8="","",IF(OR(P8="",P8=0),"No balance",IF(ABS(I8-P8)<1,"Yes",IF(ABS(I8/P8-1)<0.02,"Within 2%",IF(ABS(I8/P8-1)<0.05,"Within 5%","No"))))) | U8: =IF($J8="","",IF(N8="","",IF(ABS(F8-N8)<1,"Yes",IF(ABS(G8-N8)<1,"Disbursed = sanction","No")))) | V8: =IF(OR($J8="",Q8="",E8=""),"",ABS(E8-Q8)) | W8: Yes
A9: 12 | B9: ='Loan Book'!D12 | C9: ='Loan Book'!E12 | D9: ='Loan Book'!F12 | E9: ='Loan Book'!G12 | F9: ='Loan Book'!L12 | G9: ='Loan Book'!M12 | H9: ='Loan Book'!O12 | I9: ='Loan Book'!R12 | J9: 000104430000008 | K9: High | L9: =IFERROR(INDEX('E-Banker master'!$B$2:$B$186,MATCH($J9,'E-Banker master'!$A$2:$A$186,0)),"") | M9: =IFERROR(INDEX('E-Banker master'!$H$2:$H$186,MATCH($J9,'E-Banker master'!$A$2:$A$186,0)),"") | N9: =IFERROR(INDEX('E-Banker master'!$I$2:$I$186,MATCH($J9,'E-Banker master'!$A$2:$A$186,0)),"") | O9: =IFERROR(INDEX('E-Banker master'!$N$2:$N$186,MATCH($J9,'E-Banker master'!$A$2:$A$186,0)),"") | P9: =IFERROR(INDEX('E-Banker master'!$P$2:$P$186,MATCH($J9,'E-Banker master'!$A$2:$A$186,0)),"") | Q9: =IFERROR(INDEX('E-Banker master'!$Q$2:$Q$186,MATCH($J9,'E-Banker master'!$A$2:$A$186,0)),"") | R9: =IFERROR(INDEX('E-Banker master'!$E$2:$E$186,MATCH($J9,'E-Banker master'!$A$2:$A$186,0)),"") | S9: =IF($J9="","",IF(O9="","No take-on posting",IF(ABS(H9-O9)<1,"Yes",IF(ABS(H9/O9-1)<0.01,"Within 1%","No")))) | T9: =IF($J9="","",IF(OR(P9="",P9=0),"No balance",IF(ABS(I9-P9)<1,"Yes",IF(ABS(I9/P9-1)<0.02,"Within 2%",IF(ABS(I9/P9-1)<0.05,"Within 5%","No"))))) | U9: =IF($J9="","",IF(N9="","",IF(ABS(F9-N9)<1,"Yes",IF(ABS(G9-N9)<1,"Disbursed = sanction","No")))) | V9: =IF(OR($J9="",Q9="",E9=""),"",ABS(E9-Q9)) | W9: Yes
A10: 13 | B10: ='Loan Book'!D13 | C10: ='Loan Book'!E13 | D10: ='Loan Book'!F13 | E10: ='Loan Book'!G13 | F10: ='Loan Book'!L13 | G10: ='Loan Book'!M13 | H10: ='Loan Book'!O13 | I10: ='Loan Book'!R13 | J10: 000104420000009 | K10: High | L10: =IFERROR(INDEX('E-Banker master'!$B$2:$B$186,MATCH($J10,'E-Banker master'!$A$2:$A$186,0)),"") | M10: =IFERROR(INDEX('E-Banker master'!$H$2:$H$186,MATCH($J10,'E-Banker master'!$A$2:$A$186,0)),"") | N10: =IFERROR(INDEX('E-Banker master'!$I$2:$I$186,MATCH($J10,'E-Banker master'!$A$2:$A$186,0)),"") | O10: =IFERROR(INDEX('E-Banker master'!$N$2:$N$186,MATCH($J10,'E-Banker master'!$A$2:$A$186,0)),"") | P10: =IFERROR(INDEX('E-Banker master'!$P$2:$P$186,MATCH($J10,'E-Banker master'!$A$2:$A$186,0)),"") | Q10: =IFERROR(INDEX('E-Banker master'!$Q$2:$Q$186,MATCH($J10,'E-Banker master'!$A$2:$A$186,0)),"") | R10: =IFERROR(INDEX('E-Banker master'!$E$2:$E$186,MATCH($J10,'E-Banker master'!$A$2:$A$186,0)),"") | S10: =IF($J10="","",IF(O10="","No take-on posting",IF(ABS(H10-O10)<1,"Yes",IF(ABS(H10/O10-1)<0.01,"Within 1%","No")))) | T10: =IF($J10="","",IF(OR(P10="",P10=0),"No balance",IF(ABS(I10-P10)<1,"Yes",IF(ABS(I10/P10-1)<0.02,"Within 2%",IF(ABS(I10/P10-1)<0.05,"Within 5%","No"))))) | U10: =IF($J10="","",IF(N10="","",IF(ABS(F10-N10)<1,"Yes",IF(ABS(G10-N10)<1,"Disbursed = sanction","No")))) | V10: =IF(OR($J10="",Q10="",E10=""),"",ABS(E10-Q10)) | W10: Yes
A11: 14 | B11: ='Loan Book'!D14 | C11: ='Loan Book'!E14 | D11: ='Loan Book'!F14 | E11: ='Loan Book'!G14 | F11: ='Loan Book'!L14 | G11: ='Loan Book'!M14 | H11: ='Loan Book'!O14 | I11: ='Loan Book'!R14 | J11: 000104420000010 | K11: High | L11: =IFERROR(INDEX('E-Banker master'!$B$2:$B$186,MATCH($J11,'E-Banker master'!$A$2:$A$186,0)),"") | M11: =IFERROR(INDEX('E-Banker master'!$H$2:$H$186,MATCH($J11,'E-Banker master'!$A$2:$A$186,0)),"") | N11: =IFERROR(INDEX('E-Banker master'!$I$2:$I$186,MATCH($J11,'E-Banker master'!$A$2:$A$186,0)),"") | O11: =IFERROR(INDEX('E-Banker master'!$N$2:$N$186,MATCH($J11,'E-Banker master'!$A$2:$A$186,0)),"") | P11: =IFERROR(INDEX('E-Banker master'!$P$2:$P$186,MATCH($J11,'E-Banker master'!$A$2:$A$186,0)),"") | Q11: =IFERROR(INDEX('E-Banker master'!$Q$2:$Q$186,MATCH($J11,'E-Banker master'!$A$2:$A$186,0)),"") | R11: =IFERROR(INDEX('E-Banker master'!$E$2:$E$186,MATCH($J11,'E-Banker master'!$A$2:$A$186,0)),"") | S11: =IF($J11="","",IF(O11="","No take-on posting",IF(ABS(H11-O11)<1,"Yes",IF(ABS(H11/O11-1)<0.01,"Within 1%","No")))) | T11: =IF($J11="","",IF(OR(P11="",P11=0),"No balance",IF(ABS(I11-P11)<1,"Yes",IF(ABS(I11/P11-1)<0.02,"Within 2%",IF(ABS(I11/P11-1)<0.05,"Within 5%","No"))))) | U11: =IF($J11="","",IF(N11="","",IF(ABS(F11-N11)<1,"Yes",IF(ABS(G11-N11)<1,"Disbursed = sanction","No")))) | V11: =IF(OR($J11="",Q11="",E11=""),"",ABS(E11-Q11)) | W11: Yes
A12: 15 | B12: ='Loan Book'!D15 | C12: ='Loan Book'!E15 | D12: ='Loan Book'!F15 | E12: ='Loan Book'!G15 | F12: ='Loan Book'!L15 | G12: ='Loan Book'!M15 | H12: ='Loan Book'!O15 | I12: ='Loan Book'!R15 | J12: 000104420000012 | K12: High | L12: =IFERROR(INDEX('E-Banker master'!$B$2:$B$186,MATCH($J12,'E-Banker master'!$A$2:$A$186,0)),"") | M12: =IFERROR(INDEX('E-Banker master'!$H$2:$H$186,MATCH($J12,'E-Banker master'!$A$2:$A$186,0)),"") | N12: =IFERROR(INDEX('E-Banker master'!$I$2:$I$186,MATCH($J12,'E-Banker master'!$A$2:$A$186,0)),"") | O12: =IFERROR(INDEX('E-Banker master'!$N$2:$N$186,MATCH($J12,'E-Banker master'!$A$2:$A$186,0)),"") | P12: =IFERROR(INDEX('E-Banker master'!$P$2:$P$186,MATCH($J12,'E-Banker master'!$A$2:$A$186,0)),"") | Q12: =IFERROR(INDEX('E-Banker master'!$Q$2:$Q$186,MATCH($J12,'E-Banker master'!$A$2:$A$186,0)),"") | R12: =IFERROR(INDEX('E-Banker master'!$E$2:$E$186,MATCH($J12,'E-Banker master'!$A$2:$A$186,0)),"") | S12: =IF($J12="","",IF(O12="","No take-on posting",IF(ABS(H12-O12)<1,"Yes",IF(ABS(H12/O12-1)<0.01,"Within 1%","No")))) | T12: =IF($J12="","",IF(OR(P12="",P12=0),"No balance",IF(ABS(I12-P12)<1,"Yes",IF(ABS(I12/P12-1)<0.02,"Within 2%",IF(ABS(I12/P12-1)<0.05,"Within 5%","No"))))) | U12: =IF($J12="","",IF(N12="","",IF(ABS(F12-N12)<1,"Yes",IF(ABS(G12-N12)<1,"Disbursed = sanction","No")))) | V12: =IF(OR($J12="",Q12="",E12=""),"",ABS(E12-Q12)) | W12: Yes
A13: 16 | B13: ='Loan Book'!D16 | C13: ='Loan Book'!E16 | D13: ='Loan Book'!F16 | E13: ='Loan Book'!G16 | F13: ='Loan Book'!L16 | G13: ='Loan Book'!M16 | H13: ='Loan Book'!O16 | I13: ='Loan Book'!R16 | J13: 000104420000011 | K13: High | L13: =IFERROR(INDEX('E-Banker master'!$B$2:$B$186,MATCH($J13,'E-Banker master'!$A$2:$A$186,0)),"") | M13: =IFERROR(INDEX('E-Banker master'!$H$2:$H$186,MATCH($J13,'E-Banker master'!$A$2:$A$186,0)),"") | N13: =IFERROR(INDEX('E-Banker master'!$I$2:$I$186,MATCH($J13,'E-Banker master'!$A$2:$A$186,0)),"") | O13: =IFERROR(INDEX('E-Banker master'!$N$2:$N$186,MATCH($J13,'E-Banker master'!$A$2:$A$186,0)),"") | P13: =IFERROR(INDEX('E-Banker master'!$P$2:$P$186,MATCH($J13,'E-Banker master'!$A$2:$A$186,0)),"") | Q13: =IFERROR(INDEX('E-Banker master'!$Q$2:$Q$186,MATCH($J13,'E-Banker master'!$A$2:$A$186,0)),"") | R13: =IFERROR(INDEX('E-Banker master'!$E$2:$E$186,MATCH($J13,'E-Banker master'!$A$2:$A$186,0)),"") | S13: =IF($J13="","",IF(O13="","No take-on posting",IF(ABS(H13-O13)<1,"Yes",IF(ABS(H13/O13-1)<0.01,"Within 1%","No")))) | T13: =IF($J13="","",IF(OR(P13="",P13=0),"No balance",IF(ABS(I13-P13)<1,"Yes",IF(ABS(I13/P13-1)<0.02,"Within 2%",IF(ABS(I13/P13-1)<0.05,"Within 5%","No"))))) | U13: =IF($J13="","",IF(N13="","",IF(ABS(F13-N13)<1,"Yes",IF(ABS(G13-N13)<1,"Disbursed = sanction","No")))) | V13: =IF(OR($J13="",Q13="",E13=""),"",ABS(E13-Q13)) | W13: Yes
... A38: 41 | B38: ='Loan Book'!D41 | C38: ='Loan Book'!E41 | D38: ='Loan Book'!F41 | E38: ='Loan Book'!G41 | F38: ='Loan Book'!L41 | G38: ='Loan Book'!M41 | H38: ='Loan Book'!O41 | I38: ='Loan Book'!R41 | J38: 000104450000036 | K38: High | L38: =IFERROR(INDEX('E-Banker master'!$B$2:$B$186,MATCH($J38,'E-Banker master'!$A$2:$A$186,0)),"") | M38: =IFERROR(INDEX('E-Banker master'!$H$2:$H$186,MATCH($J38,'E-Banker master'!$A$2:$A$186,0)),"") | N38: =IFERROR(INDEX('E-Banker master'!$I$2:$I$186,MATCH($J38,'E-Banker master'!$A$2:$A$186,0)),"") | O38: =IFERROR(INDEX('E-Banker master'!$N$2:$N$186,MATCH($J38,'E-Banker master'!$A$2:$A$186,0)),"") | P38: =IFERROR(INDEX('E-Banker master'!$P$2:$P$186,MATCH($J38,'E-Banker master'!$A$2:$A$186,0)),"") | Q38: =IFERROR(INDEX('E-Banker master'!$Q$2:$Q$186,MATCH($J38,'E-Banker master'!$A$2:$A$186,0)),"") | R38: =IFERROR(INDEX('E-Banker master'!$E$2:$E$186,MATCH($J38,'E-Banker master'!$A$2:$A$186,0)),"") | S38: =IF($J38="","",IF(O38="","No take-on posting",IF(ABS(H38-O38)<1,"Yes",IF(ABS(H38/O38-1)<0.01,"Within 1%","No")))) | T38: =IF($J38="","",IF(OR(P38="",P38=0),"No balance",IF(ABS(I38-P38)<1,"Yes",IF(ABS(I38/P38-1)<0.02,"Within 2%",IF(ABS(I38/P38-1)<0.05,"Within 5%","No"))))) | U38: =IF($J38="","",IF(N38="","",IF(ABS(F38-N38)<1,"Yes",IF(ABS(G38-N38)<1,"Disbursed = sanction","No")))) | V38: =IF(OR($J38="",Q38="",E38=""),"",ABS(E38-Q38)) | W38: Yes
A39: 42 | B39: ='Loan Book'!D42 | C39: ='Loan Book'!E42 | D39: ='Loan Book'!F42 | E39: ='Loan Book'!G42 | F39: ='Loan Book'!L42 | G39: ='Loan Book'!M42 | H39: ='Loan Book'!O42 | I39: ='Loan Book'!R42 | K39: Not matched | L39: =IFERROR(INDEX('E-Banker master'!$B$2:$B$186,MATCH($J39,'E-Banker master'!$A$2:$A$186,0)),"") | M39: =IFERROR(INDEX('E-Banker master'!$H$2:$H$186,MATCH($J39,'E-Banker master'!$A$2:$A$186,0)),"") | N39: =IFERROR(INDEX('E-Banker master'!$I$2:$I$186,MATCH($J39,'E-Banker master'!$A$2:$A$186,0)),"") | O39: =IFERROR(INDEX('E-Banker master'!$N$2:$N$186,MATCH($J39,'E-Banker master'!$A$2:$A$186,0)),"") | P39: =IFERROR(INDEX('E-Banker master'!$P$2:$P$186,MATCH($J39,'E-Banker master'!$A$2:$A$186,0)),"") | Q39: =IFERROR(INDEX('E-Banker master'!$Q$2:$Q$186,MATCH($J39,'E-Banker master'!$A$2:$A$186,0)),"") | R39: =IFERROR(INDEX('E-Banker master'!$E$2:$E$186,MATCH($J39,'E-Banker master'!$A$2:$A$186,0)),"") | S39: =IF($J39="","",IF(O39="","No take-on posting",IF(ABS(H39-O39)<1,"Yes",IF(ABS(H39/O39-1)<0.01,"Within 1%","No")))) | T39: =IF($J39="","",IF(OR(P39="",P39=0),"No balance",IF(ABS(I39-P39)<1,"Yes",IF(ABS(I39/P39-1)<0.02,"Within 2%",IF(ABS(I39/P39-1)<0.05,"Within 5%","No"))))) | U39: =IF($J39="","",IF(N39="","",IF(ABS(F39-N39)<1,"Yes",IF(ABS(G39-N39)<1,"Disbursed = sanction","No")))) | V39: =IF(OR($J39="",Q39="",E39=""),"",ABS(E39-Q39)) | W39: No
A40: 43 | B40: ='Loan Book'!D43 | C40: ='Loan Book'!E43 | D40: ='Loan Book'!F43 | E40: ='Loan Book'!G43 | F40: ='Loan Book'!L43 | G40: ='Loan Book'!M43 | H40: ='Loan Book'!O43 | I40: ='Loan Book'!R43 | J40: 000104450000038 | K40: High | L40: =IFERROR(INDEX('E-Banker master'!$B$2:$B$186,MATCH($J40,'E-Banker master'!$A$2:$A$186,0)),"") | M40: =IFERROR(INDEX('E-Banker master'!$H$2:$H$186,MATCH($J40,'E-Banker master'!$A$2:$A$186,0)),"") | N40: =IFERROR(INDEX('E-Banker master'!$I$2:$I$186,MATCH($J40,'E-Banker master'!$A$2:$A$186,0)),"") | O40: =IFERROR(INDEX('E-Banker master'!$N$2:$N$186,MATCH($J40,'E-Banker master'!$A$2:$A$186,0)),"") | P40: =IFERROR(INDEX('E-Banker master'!$P$2:$P$186,MATCH($J40,'E-Banker master'!$A$2:$A$186,0)),"") | Q40: =IFERROR(INDEX('E-Banker master'!$Q$2:$Q$186,MATCH($J40,'E-Banker master'!$A$2:$A$186,0)),"") | R40: =IFERROR(INDEX('E-Banker master'!$E$2:$E$186,MATCH($J40,'E-Banker master'!$A$2:$A$186,0)),"") | S40: =IF($J40="","",IF(O40="","No take-on posting",IF(ABS(H40-O40)<1,"Yes",IF(ABS(H40/O40-1)<0.01,"Within 1%","No")))) | T40: =IF($J40="","",IF(OR(P40="",P40=0),"No balance",IF(ABS(I40-P40)<1,"Yes",IF(ABS(I40/P40-1)<0.02,"Within 2%",IF(ABS(I40/P40-1)<0.05,"Within 5%","No"))))) | U40: =IF($J40="","",IF(N40="","",IF(ABS(F40-N40)<1,"Yes",IF(ABS(G40-N40)<1,"Disbursed = sanction","No")))) | V40: =IF(OR($J40="",Q40="",E40=""),"",ABS(E40-Q40)) | W40: Yes
A41: 44 | B41: ='Loan Book'!D44 | C41: ='Loan Book'!E44 | D41: ='Loan Book'!F44 | E41: ='Loan Book'!G44 | F41: ='Loan Book'!L44 | G41: ='Loan Book'!M44 | H41: ='Loan Book'!O44 | I41: ='Loan Book'!R44 | J41: 000104450000039 | K41: High | L41: =IFERROR(INDEX('E-Banker master'!$B$2:$B$186,MATCH($J41,'E-Banker master'!$A$2:$A$186,0)),"") | M41: =IFERROR(INDEX('E-Banker master'!$H$2:$H$186,MATCH($J41,'E-Banker master'!$A$2:$A$186,0)),"") | N41: =IFERROR(INDEX('E-Banker master'!$I$2:$I$186,MATCH($J41,'E-Banker master'!$A$2:$A$186,0)),"") | O41: =IFERROR(INDEX('E-Banker master'!$N$2:$N$186,MATCH($J41,'E-Banker master'!$A$2:$A$186,0)),"") | P41: =IFERROR(INDEX('E-Banker master'!$P$2:$P$186,MATCH($J41,'E-Banker master'!$A$2:$A$186,0)),"") | Q41: =IFERROR(INDEX('E-Banker master'!$Q$2:$Q$186,MATCH($J41,'E-Banker master'!$A$2:$A$186,0)),"") | R41: =IFERROR(INDEX('E-Banker master'!$E$2:$E$186,MATCH($J41,'E-Banker master'!$A$2:$A$186,0)),"") | S41: =IF($J41="","",IF(O41="","No take-on posting",IF(ABS(H41-O41)<1,"Yes",IF(ABS(H41/O41-1)<0.01,"Within 1%","No")))) | T41: =IF($J41="","",IF(OR(P41="",P41=0),"No balance",IF(ABS(I41-P41)<1,"Yes",IF(ABS(I41/P41-1)<0.02,"Within 2%",IF(ABS(I41/P41-1)<0.05,"Within 5%","No"))))) | U41: =IF($J41="","",IF(N41="","",IF(ABS(F41-N41)<1,"Yes",IF(ABS(G41-N41)<1,"Disbursed = sanction","No")))) | V41: =IF(OR($J41="",Q41="",E41=""),"",ABS(E41-Q41)) | W41: Yes
A42: 45 | B42: ='Loan Book'!D45 | C42: ='Loan Book'!E45 | D42: ='Loan Book'!F45 | E42: ='Loan Book'!G45 | F42: ='Loan Book'!L45 | G42: ='Loan Book'!M45 | H42: ='Loan Book'!O45 | I42: ='Loan Book'!R45 | J42: 000104420000040 | K42: High | L42: =IFERROR(INDEX('E-Banker master'!$B$2:$B$186,MATCH($J42,'E-Banker master'!$A$2:$A$186,0)),"") | M42: =IFERROR(INDEX('E-Banker master'!$H$2:$H$186,MATCH($J42,'E-Banker master'!$A$2:$A$186,0)),"") | N42: =IFERROR(INDEX('E-Banker master'!$I$2:$I$186,MATCH($J42,'E-Banker master'!$A$2:$A$186,0)),"") | O42: =IFERROR(INDEX('E-Banker master'!$N$2:$N$186,MATCH($J42,'E-Banker master'!$A$2:$A$186,0)),"") | P42: =IFERROR(INDEX('E-Banker master'!$P$2:$P$186,MATCH($J42,'E-Banker master'!$A$2:$A$186,0)),"") | Q42: =IFERROR(INDEX('E-Banker master'!$Q$2:$Q$186,MATCH($J42,'E-Banker master'!$A$2:$A$186,0)),"") | R42: =IFERROR(INDEX('E-Banker master'!$E$2:$E$186,MATCH($J42,'E-Banker master'!$A$2:$A$186,0)),"") | S42: =IF($J42="","",IF(O42="","No take-on posting",IF(ABS(H42-O42)<1,"Yes",IF(ABS(H42/O42-1)<0.01,"Within 1%","No")))) | T42: =IF($J42="","",IF(OR(P42="",P42=0),"No balance",IF(ABS(I42-P42)<1,"Yes",IF(ABS(I42/P42-1)<0.02,"Within 2%",IF(ABS(I42/P42-1)<0.05,"Within 5%","No"))))) | U42: =IF($J42="","",IF(N42="","",IF(ABS(F42-N42)<1,"Yes",IF(ABS(G42-N42)<1,"Disbursed = sanction","No")))) | V42: =IF(OR($J42="",Q42="",E42=""),"",ABS(E42-Q42)) | W42: Yes
A43: 46 | B43: ='Loan Book'!D46 | C43: ='Loan Book'!E46 | D43: ='Loan Book'!F46 | E43: ='Loan Book'!G46 | F43: ='Loan Book'!L46 | G43: ='Loan Book'!M46 | H43: ='Loan Book'!O46 | I43: ='Loan Book'!R46 | J43: 000104450000041 | K43: High | L43: =IFERROR(INDEX('E-Banker master'!$B$2:$B$186,MATCH($J43,'E-Banker master'!$A$2:$A$186,0)),"") | M43: =IFERROR(INDEX('E-Banker master'!$H$2:$H$186,MATCH($J43,'E-Banker master'!$A$2:$A$186,0)),"") | N43: =IFERROR(INDEX('E-Banker master'!$I$2:$I$186,MATCH($J43,'E-Banker master'!$A$2:$A$186,0)),"") | O43: =IFERROR(INDEX('E-Banker master'!$N$2:$N$186,MATCH($J43,'E-Banker master'!$A$2:$A$186,0)),"") | P43: =IFERROR(INDEX('E-Banker master'!$P$2:$P$186,MATCH($J43,'E-Banker master'!$A$2:$A$186,0)),"") | Q43: =IFERROR(INDEX('E-Banker master'!$Q$2:$Q$186,MATCH($J43,'E-Banker master'!$A$2:$A$186,0)),"") | R43: =IFERROR(INDEX('E-Banker master'!$E$2:$E$186,MATCH($J43,'E-Banker master'!$A$2:$A$186,0)),"") | S43: =IF($J43="","",IF(O43="","No take-on posting",IF(ABS(H43-O43)<1,"Yes",IF(ABS(H43/O43-1)<0.01,"Within 1%","No")))) | T43: =IF($J43="","",IF(OR(P43="",P43=0),"No balance",IF(ABS(I43-P43)<1,"Yes",IF(ABS(I43/P43-1)<0.02,"Within 2%",IF(ABS(I43/P43-1)<0.05,"Within 5%","No"))))) | U43: =IF($J43="","",IF(N43="","",IF(ABS(F43-N43)<1,"Yes",IF(ABS(G43-N43)<1,"Disbursed = sanction","No")))) | V43: =IF(OR($J43="",Q43="",E43=""),"",ABS(E43-Q43)) | W43: Yes
A44: 47 | B44: ='Loan Book'!D47 | C44: ='Loan Book'!E47 | D44: ='Loan Book'!F47 | E44: ='Loan Book'!G47 | F44: ='Loan Book'!L47 | G44: ='Loan Book'!M47 | H44: ='Loan Book'!O47 | I44: ='Loan Book'!R47 | J44: 000104450000042 | K44: High | L44: =IFERROR(INDEX('E-Banker master'!$B$2:$B$186,MATCH($J44,'E-Banker master'!$A$2:$A$186,0)),"") | M44: =IFERROR(INDEX('E-Banker master'!$H$2:$H$186,MATCH($J44,'E-Banker master'!$A$2:$A$186,0)),"") | N44: =IFERROR(INDEX('E-Banker master'!$I$2:$I$186,MATCH($J44,'E-Banker master'!$A$2:$A$186,0)),"") | O44: =IFERROR(INDEX('E-Banker master'!$N$2:$N$186,MATCH($J44,'E-Banker master'!$A$2:$A$186,0)),"") | P44: =IFERROR(INDEX('E-Banker master'!$P$2:$P$186,MATCH($J44,'E-Banker master'!$A$2:$A$186,0)),"") | Q44: =IFERROR(INDEX('E-Banker master'!$Q$2:$Q$186,MATCH($J44,'E-Banker master'!$A$2:$A$186,0)),"") | R44: =IFERROR(INDEX('E-Banker master'!$E$2:$E$186,MATCH($J44,'E-Banker master'!$A$2:$A$186,0)),"") | S44: =IF($J44="","",IF(O44="","No take-on posting",IF(ABS(H44-O44)<1,"Yes",IF(ABS(H44/O44-1)<0.01,"Within 1%","No")))) | T44: =IF($J44="","",IF(OR(P44="",P44=0),"No balance",IF(ABS(I44-P44)<1,"Yes",IF(ABS(I44/P44-1)<0.02,"Within 2%",IF(ABS(I44/P44-1)<0.05,"Within 5%","No"))))) | U44: =IF($J44="","",IF(N44="","",IF(ABS(F44-N44)<1,"Yes",IF(ABS(G44-N44)<1,"Disbursed = sanction","No")))) | V44: =IF(OR($J44="",Q44="",E44=""),"",ABS(E44-Q44)) | W44: Yes
A45: 48 | B45: ='Loan Book'!D48 | C45: ='Loan Book'!E48 | D45: ='Loan Book'!F48 | E45: ='Loan Book'!G48 | F45: ='Loan Book'!L48 | G45: ='Loan Book'!M48 | H45: ='Loan Book'!O48 | I45: ='Loan Book'!R48 | J45: 000104420000043 | K45: High | L45: =IFERROR(INDEX('E-Banker master'!$B$2:$B$186,MATCH($J45,'E-Banker master'!$A$2:$A$186,0)),"") | M45: =IFERROR(INDEX('E-Banker master'!$H$2:$H$186,MATCH($J45,'E-Banker master'!$A$2:$A$186,0)),"") | N45: =IFERROR(INDEX('E-Banker master'!$I$2:$I$186,MATCH($J45,'E-Banker master'!$A$2:$A$186,0)),"") | O45: =IFERROR(INDEX('E-Banker master'!$N$2:$N$186,MATCH($J45,'E-Banker master'!$A$2:$A$186,0)),"") | P45: =IFERROR(INDEX('E-Banker master'!$P$2:$P$186,MATCH($J45,'E-Banker master'!$A$2:$A$186,0)),"") | Q45: =IFERROR(INDEX('E-Banker master'!$Q$2:$Q$186,MATCH($J45,'E-Banker master'!$A$2:$A$186,0)),"") | R45: =IFERROR(INDEX('E-Banker master'!$E$2:$E$186,MATCH($J45,'E-Banker master'!$A$2:$A$186,0)),"") | S45: =IF($J45="","",IF(O45="","No take-on posting",IF(ABS(H45-O45)<1,"Yes",IF(ABS(H45/O45-1)<0.01,"Within 1%","No")))) | T45: =IF($J45="","",IF(OR(P45="",P45=0),"No balance",IF(ABS(I45-P45)<1,"Yes",IF(ABS(I45/P45-1)<0.02,"Within 2%",IF(ABS(I45/P45-1)<0.05,"Within 5%","No"))))) | U45: =IF($J45="","",IF(N45="","",IF(ABS(F45-N45)<1,"Yes",IF(ABS(G45-N45)<1,"Disbursed = sanction","No")))) | V45: =IF(OR($J45="",Q45="",E45=""),"",ABS(E45-Q45)) | W45: Yes
A46: 49 | B46: ='Loan Book'!D49 | C46: ='Loan Book'!E49 | D46: ='Loan Book'!F49 | E46: ='Loan Book'!G49 | F46: ='Loan Book'!L49 | G46: ='Loan Book'!M49 | H46: ='Loan Book'!O49 | I46: ='Loan Book'!R49 | J46: 000104420000044 | K46: High | L46: =IFERROR(INDEX('E-Banker master'!$B$2:$B$186,MATCH($J46,'E-Banker master'!$A$2:$A$186,0)),"") | M46: =IFERROR(INDEX('E-Banker master'!$H$2:$H$186,MATCH($J46,'E-Banker master'!$A$2:$A$186,0)),"") | N46: =IFERROR(INDEX('E-Banker master'!$I$2:$I$186,MATCH($J46,'E-Banker master'!$A$2:$A$186,0)),"") | O46: =IFERROR(INDEX('E-Banker master'!$N$2:$N$186,MATCH($J46,'E-Banker master'!$A$2:$A$186,0)),"") | P46: =IFERROR(INDEX('E-Banker master'!$P$2:$P$186,MATCH($J46,'E-Banker master'!$A$2:$A$186,0)),"") | Q46: =IFERROR(INDEX('E-Banker master'!$Q$2:$Q$186,MATCH($J46,'E-Banker master'!$A$2:$A$186,0)),"") | R46: =IFERROR(INDEX('E-Banker master'!$E$2:$E$186,MATCH($J46,'E-Banker master'!$A$2:$A$186,0)),"") | S46: =IF($J46="","",IF(O46="","No take-on posting",IF(ABS(H46-O46)<1,"Yes",IF(ABS(H46/O46-1)<0.01,"Within 1%","No")))) | T46: =IF($J46="","",IF(OR(P46="",P46=0),"No balance",IF(ABS(I46-P46)<1,"Yes",IF(ABS(I46/P46-1)<0.02,"Within 2%",IF(ABS(I46/P46-1)<0.05,"Within 5%","No"))))) | U46: =IF($J46="","",IF(N46="","",IF(ABS(F46-N46)<1,"Yes",IF(ABS(G46-N46)<1,"Disbursed = sanction","No")))) | V46: =IF(OR($J46="",Q46="",E46=""),"",ABS(E46-Q46)) | W46: Yes
A47: 50 | B47: ='Loan Book'!D50 | C47: ='Loan Book'!E50 | D47: ='Loan Book'!F50 | E47: ='Loan Book'!G50 | F47: ='Loan Book'!L50 | G47: ='Loan Book'!M50 | H47: ='Loan Book'!O50 | I47: ='Loan Book'!R50 | J47: 000104450000045 | K47: High | L47: =IFERROR(INDEX('E-Banker master'!$B$2:$B$186,MATCH($J47,'E-Banker master'!$A$2:$A$186,0)),"") | M47: =IFERROR(INDEX('E-Banker master'!$H$2:$H$186,MATCH($J47,'E-Banker master'!$A$2:$A$186,0)),"") | N47: =IFERROR(INDEX('E-Banker master'!$I$2:$I$186,MATCH($J47,'E-Banker master'!$A$2:$A$186,0)),"") | O47: =IFERROR(INDEX('E-Banker master'!$N$2:$N$186,MATCH($J47,'E-Banker master'!$A$2:$A$186,0)),"") | P47: =IFERROR(INDEX('E-Banker master'!$P$2:$P$186,MATCH($J47,'E-Banker master'!$A$2:$A$186,0)),"") | Q47: =IFERROR(INDEX('E-Banker master'!$Q$2:$Q$186,MATCH($J47,'E-Banker master'!$A$2:$A$186,0)),"") | R47: =IFERROR(INDEX('E-Banker master'!$E$2:$E$186,MATCH($J47,'E-Banker master'!$A$2:$A$186,0)),"") | S47: =IF($J47="","",IF(O47="","No take-on posting",IF(ABS(H47-O47)<1,"Yes",IF(ABS(H47/O47-1)<0.01,"Within 1%","No")))) | T47: =IF($J47="","",IF(OR(P47="",P47=0),"No balance",IF(ABS(I47-P47)<1,"Yes",IF(ABS(I47/P47-1)<0.02,"Within 2%",IF(ABS(I47/P47-1)<0.05,"Within 5%","No"))))) | U47: =IF($J47="","",IF(N47="","",IF(ABS(F47-N47)<1,"Yes",IF(ABS(G47-N47)<1,"Disbursed = sanction","No")))) | V47: =IF(OR($J47="",Q47="",E47=""),"",ABS(E47-Q47)) | W47: Yes
A48: 51 | B48: ='Loan Book'!D51 | C48: ='Loan Book'!E51 | D48: ='Loan Book'!F51 | E48: ='Loan Book'!G51 | F48: ='Loan Book'!L51 | G48: ='Loan Book'!M51 | H48: ='Loan Book'!O51 | I48: ='Loan Book'!R51 | J48: 000104450000046 | K48: High | L48: =IFERROR(INDEX('E-Banker master'!$B$2:$B$186,MATCH($J48,'E-Banker master'!$A$2:$A$186,0)),"") | M48: =IFERROR(INDEX('E-Banker master'!$H$2:$H$186,MATCH($J48,'E-Banker master'!$A$2:$A$186,0)),"") | N48: =IFERROR(INDEX('E-Banker master'!$I$2:$I$186,MATCH($J48,'E-Banker master'!$A$2:$A$186,0)),"") | O48: =IFERROR(INDEX('E-Banker master'!$N$2:$N$186,MATCH($J48,'E-Banker master'!$A$2:$A$186,0)),"") | P48: =IFERROR(INDEX('E-Banker master'!$P$2:$P$186,MATCH($J48,'E-Banker master'!$A$2:$A$186,0)),"") | Q48: =IFERROR(INDEX('E-Banker master'!$Q$2:$Q$186,MATCH($J48,'E-Banker master'!$A$2:$A$186,0)),"") | R48: =IFERROR(INDEX('E-Banker master'!$E$2:$E$186,MATCH($J48,'E-Banker master'!$A$2:$A$186,0)),"") | S48: =IF($J48="","",IF(O48="","No take-on posting",IF(ABS(H48-O48)<1,"Yes",IF(ABS(H48/O48-1)<0.01,"Within 1%","No")))) | T48: =IF($J48="","",IF(OR(P48="",P48=0),"No balance",IF(ABS(I48-P48)<1,"Yes",IF(ABS(I48/P48-1)<0.02,"Within 2%",IF(ABS(I48/P48-1)<0.05,"Within 5%","No"))))) | U48: =IF($J48="","",IF(N48="","",IF(ABS(F48-N48)<1,"Yes",IF(ABS(G48-N48)<1,"Disbursed = sanction","No")))) | V48: =IF(OR($J48="",Q48="",E48=""),"",ABS(E48-Q48)) | W48: Yes
A49: 52 | B49: ='Loan Book'!D52 | C49: ='Loan Book'!E52 | D49: ='Loan Book'!F52 | E49: ='Loan Book'!G52 | F49: ='Loan Book'!L52 | G49: ='Loan Book'!M52 | H49: ='Loan Book'!O52 | I49: ='Loan Book'!R52 | J49: 000104450000047 | K49: High | L49: =IFERROR(INDEX('E-Banker master'!$B$2:$B$186,MATCH($J49,'E-Banker master'!$A$2:$A$186,0)),"") | M49: =IFERROR(INDEX('E-Banker master'!$H$2:$H$186,MATCH($J49,'E-Banker master'!$A$2:$A$186,0)),"") | N49: =IFERROR(INDEX('E-Banker master'!$I$2:$I$186,MATCH($J49,'E-Banker master'!$A$2:$A$186,0)),"") | O49: =IFERROR(INDEX('E-Banker master'!$N$2:$N$186,MATCH($J49,'E-Banker master'!$A$2:$A$186,0)),"") | P49: =IFERROR(INDEX('E-Banker master'!$P$2:$P$186,MATCH($J49,'E-Banker master'!$A$2:$A$186,0)),"") | Q49: =IFERROR(INDEX('E-Banker master'!$Q$2:$Q$186,MATCH($J49,'E-Banker master'!$A$2:$A$186,0)),"") | R49: =IFERROR(INDEX('E-Banker master'!$E$2:$E$186,MATCH($J49,'E-Banker master'!$A$2:$A$186,0)),"") | S49: =IF($J49="","",IF(O49="","No take-on posting",IF(ABS(H49-O49)<1,"Yes",IF(ABS(H49/O49-1)<0.01,"Within 1%","No")))) | T49: =IF($J49="","",IF(OR(P49="",P49=0),"No balance",IF(ABS(I49-P49)<1,"Yes",IF(ABS(I49/P49-1)<0.02,"Within 2%",IF(ABS(I49/P49-1)<0.05,"Within 5%","No"))))) | U49: =IF($J49="","",IF(N49="","",IF(ABS(F49-N49)<1,"Yes",IF(ABS(G49-N49)<1,"Disbursed = sanction","No")))) | V49: =IF(OR($J49="",Q49="",E49=""),"",ABS(E49-Q49)) | W49: Yes
A50: 53 | B50: ='Loan Book'!D53 | C50: ='Loan Book'!E53 | D50: ='Loan Book'!F53 | E50: ='Loan Book'!G53 | F50: ='Loan Book'!L53 | G50: ='Loan Book'!M53 | H50: ='Loan Book'!O53 | I50: ='Loan Book'!R53 | J50: 000104450000048 | K50: High | L50: =IFERROR(INDEX('E-Banker master'!$B$2:$B$186,MATCH($J50,'E-Banker master'!$A$2:$A$186,0)),"") | M50: =IFERROR(INDEX('E-Banker master'!$H$2:$H$186,MATCH($J50,'E-Banker master'!$A$2:$A$186,0)),"") | N50: =IFERROR(INDEX('E-Banker master'!$I$2:$I$186,MATCH($J50,'E-Banker master'!$A$2:$A$186,0)),"") | O50: =IFERROR(INDEX('E-Banker master'!$N$2:$N$186,MATCH($J50,'E-Banker master'!$A$2:$A$186,0)),"") | P50: =IFERROR(INDEX('E-Banker master'!$P$2:$P$186,MATCH($J50,'E-Banker master'!$A$2:$A$186,0)),"") | Q50: =IFERROR(INDEX('E-Banker master'!$Q$2:$Q$186,MATCH($J50,'E-Banker master'!$A$2:$A$186,0)),"") | R50: =IFERROR(INDEX('E-Banker master'!$E$2:$E$186,MATCH($J50,'E-Banker master'!$A$2:$A$186,0)),"") | S50: =IF($J50="","",IF(O50="","No take-on posting",IF(ABS(H50-O50)<1,"Yes",IF(ABS(H50/O50-1)<0.01,"Within 1%","No")))) | T50: =IF($J50="","",IF(OR(P50="",P50=0),"No balance",IF(ABS(I50-P50)<1,"Yes",IF(ABS(I50/P50-1)<0.02,"Within 2%",IF(ABS(I50/P50-1)<0.05,"Within 5%","No"))))) | U50: =IF($J50="","",IF(N50="","",IF(ABS(F50-N50)<1,"Yes",IF(ABS(G50-N50)<1,"Disbursed = sanction","No")))) | V50: =IF(OR($J50="",Q50="",E50=""),"",ABS(E50-Q50)) | W50: Yes
A51: 54 | B51: ='Loan Book'!D54 | C51: ='Loan Book'!E54 | D51: ='Loan Book'!F54 | E51: ='Loan Book'!G54 | F51: ='Loan Book'!L54 | G51: ='Loan Book'!M54 | H51: ='Loan Book'!O54 | I51: ='Loan Book'!R54 | J51: 000104450000049 | K51: High | L51: =IFERROR(INDEX('E-Banker master'!$B$2:$B$186,MATCH($J51,'E-Banker master'!$A$2:$A$186,0)),"") | M51: =IFERROR(INDEX('E-Banker master'!$H$2:$H$186,MATCH($J51,'E-Banker master'!$A$2:$A$186,0)),"") | N51: =IFERROR(INDEX('E-Banker master'!$I$2:$I$186,MATCH($J51,'E-Banker master'!$A$2:$A$186,0)),"") | O51: =IFERROR(INDEX('E-Banker master'!$N$2:$N$186,MATCH($J51,'E-Banker master'!$A$2:$A$186,0)),"") | P51: =IFERROR(INDEX('E-Banker master'!$P$2:$P$186,MATCH($J51,'E-Banker master'!$A$2:$A$186,0)),"") | Q51: =IFERROR(INDEX('E-Banker master'!$Q$2:$Q$186,MATCH($J51,'E-Banker master'!$A$2:$A$186,0)),"") | R51: =IFERROR(INDEX('E-Banker master'!$E$2:$E$186,MATCH($J51,'E-Banker master'!$A$2:$A$186,0)),"") | S51: =IF($J51="","",IF(O51="","No take-on posting",IF(ABS(H51-O51)<1,"Yes",IF(ABS(H51/O51-1)<0.01,"Within 1%","No")))) | T51: =IF($J51="","",IF(OR(P51="",P51=0),"No balance",IF(ABS(I51-P51)<1,"Yes",IF(ABS(I51/P51-1)<0.02,"Within 2%",IF(ABS(I51/P51-1)<0.05,"Within 5%","No"))))) | U51: =IF($J51="","",IF(N51="","",IF(ABS(F51-N51)<1,"Yes",IF(ABS(G51-N51)<1,"Disbursed = sanction","No")))) | V51: =IF(OR($J51="",Q51="",E51=""),"",ABS(E51-Q51)) | W51: Yes
... A104: 107 | B104: ='Loan Book'!D107 | C104: ='Loan Book'!E107 | D104: ='Loan Book'!F107 | E104: ='Loan Book'!G107 | F104: ='Loan Book'!L107 | G104: ='Loan Book'!M107 | H104: ='Loan Book'!O107 | I104: ='Loan Book'!R107 | J104: 000104430000064 | K104: High | L104: =IFERROR(INDEX('E-Banker master'!$B$2:$B$186,MATCH($J104,'E-Banker master'!$A$2:$A$186,0)),"") | M104: =IFERROR(INDEX('E-Banker master'!$H$2:$H$186,MATCH($J104,'E-Banker master'!$A$2:$A$186,0)),"") | N104: =IFERROR(INDEX('E-Banker master'!$I$2:$I$186,MATCH($J104,'E-Banker master'!$A$2:$A$186,0)),"") | O104: =IFERROR(INDEX('E-Banker master'!$N$2:$N$186,MATCH($J104,'E-Banker master'!$A$2:$A$186,0)),"") | P104: =IFERROR(INDEX('E-Banker master'!$P$2:$P$186,MATCH($J104,'E-Banker master'!$A$2:$A$186,0)),"") | Q104: =IFERROR(INDEX('E-Banker master'!$Q$2:$Q$186,MATCH($J104,'E-Banker master'!$A$2:$A$186,0)),"") | R104: =IFERROR(INDEX('E-Banker master'!$E$2:$E$186,MATCH($J104,'E-Banker master'!$A$2:$A$186,0)),"") | S104: =IF($J104="","",IF(O104="","No take-on posting",IF(ABS(H104-O104)<1,"Yes",IF(ABS(H104/O104-1)<0.01,"Within 1%","No")))) | T104: =IF($J104="","",IF(OR(P104="",P104=0),"No balance",IF(ABS(I104-P104)<1,"Yes",IF(ABS(I104/P104-1)<0.02,"Within 2%",IF(ABS(I104/P104-1)<0.05,"Within 5%","No"))))) | U104: =IF($J104="","",IF(N104="","",IF(ABS(F104-N104)<1,"Yes",IF(ABS(G104-N104)<1,"Disbursed = sanction","No")))) | V104: =IF(OR($J104="",Q104="",E104=""),"",ABS(E104-Q104)) | W104: Yes
A105: 111 | B105: ='Loan Book'!D111 | C105: ='Loan Book'!E111 | D105: ='Loan Book'!F111 | E105: ='Loan Book'!G111 | F105: ='Loan Book'!L111 | G105: ='Loan Book'!M111 | H105: ='Loan Book'!O111 | I105: ='Loan Book'!R111 | K105: Not matched | L105: =IFERROR(INDEX('E-Banker master'!$B$2:$B$186,MATCH($J105,'E-Banker master'!$A$2:$A$186,0)),"") | M105: =IFERROR(INDEX('E-Banker master'!$H$2:$H$186,MATCH($J105,'E-Banker master'!$A$2:$A$186,0)),"") | N105: =IFERROR(INDEX('E-Banker master'!$I$2:$I$186,MATCH($J105,'E-Banker master'!$A$2:$A$186,0)),"") | O105: =IFERROR(INDEX('E-Banker master'!$N$2:$N$186,MATCH($J105,'E-Banker master'!$A$2:$A$186,0)),"") | P105: =IFERROR(INDEX('E-Banker master'!$P$2:$P$186,MATCH($J105,'E-Banker master'!$A$2:$A$186,0)),"") | Q105: =IFERROR(INDEX('E-Banker master'!$Q$2:$Q$186,MATCH($J105,'E-Banker master'!$A$2:$A$186,0)),"") | R105: =IFERROR(INDEX('E-Banker master'!$E$2:$E$186,MATCH($J105,'E-Banker master'!$A$2:$A$186,0)),"") | S105: =IF($J105="","",IF(O105="","No take-on posting",IF(ABS(H105-O105)<1,"Yes",IF(ABS(H105/O105-1)<0.01,"Within 1%","No")))) | T105: =IF($J105="","",IF(OR(P105="",P105=0),"No balance",IF(ABS(I105-P105)<1,"Yes",IF(ABS(I105/P105-1)<0.02,"Within 2%",IF(ABS(I105/P105-1)<0.05,"Within 5%","No"))))) | U105: =IF($J105="","",IF(N105="","",IF(ABS(F105-N105)<1,"Yes",IF(ABS(G105-N105)<1,"Disbursed = sanction","No")))) | V105: =IF(OR($J105="",Q105="",E105=""),"",ABS(E105-Q105)) | W105: No
A106: 112 | B106: ='Loan Book'!D112 | C106: ='Loan Book'!E112 | D106: ='Loan Book'!F112 | E106: ='Loan Book'!G112 | F106: ='Loan Book'!L112 | G106: ='Loan Book'!M112 | H106: ='Loan Book'!O112 | I106: ='Loan Book'!R112 | K106: Not matched | L106: =IFERROR(INDEX('E-Banker master'!$B$2:$B$186,MATCH($J106,'E-Banker master'!$A$2:$A$186,0)),"") | M106: =IFERROR(INDEX('E-Banker master'!$H$2:$H$186,MATCH($J106,'E-Banker master'!$A$2:$A$186,0)),"") | N106: =IFERROR(INDEX('E-Banker master'!$I$2:$I$186,MATCH($J106,'E-Banker master'!$A$2:$A$186,0)),"") | O106: =IFERROR(INDEX('E-Banker master'!$N$2:$N$186,MATCH($J106,'E-Banker master'!$A$2:$A$186,0)),"") | P106: =IFERROR(INDEX('E-Banker master'!$P$2:$P$186,MATCH($J106,'E-Banker master'!$A$2:$A$186,0)),"") | Q106: =IFERROR(INDEX('E-Banker master'!$Q$2:$Q$186,MATCH($J106,'E-Banker master'!$A$2:$A$186,0)),"") | R106: =IFERROR(INDEX('E-Banker master'!$E$2:$E$186,MATCH($J106,'E-Banker master'!$A$2:$A$186,0)),"") | S106: =IF($J106="","",IF(O106="","No take-on posting",IF(ABS(H106-O106)<1,"Yes",IF(ABS(H106/O106-1)<0.01,"Within 1%","No")))) | T106: =IF($J106="","",IF(OR(P106="",P106=0),"No balance",IF(ABS(I106-P106)<1,"Yes",IF(ABS(I106/P106-1)<0.02,"Within 2%",IF(ABS(I106/P106-1)<0.05,"Within 5%","No"))))) | U106: =IF($J106="","",IF(N106="","",IF(ABS(F106-N106)<1,"Yes",IF(ABS(G106-N106)<1,"Disbursed = sanction","No")))) | V106: =IF(OR($J106="",Q106="",E106=""),"",ABS(E106-Q106)) | W106: No
A107: 113 | B107: ='Loan Book'!D113 | C107: ='Loan Book'!E113 | D107: ='Loan Book'!F113 | E107: ='Loan Book'!G113 | F107: ='Loan Book'!L113 | G107: ='Loan Book'!M113 | H107: ='Loan Book'!O113 | I107: ='Loan Book'!R113 | K107: Not matched | L107: =IFERROR(INDEX('E-Banker master'!$B$2:$B$186,MATCH($J107,'E-Banker master'!$A$2:$A$186,0)),"") | M107: =IFERROR(INDEX('E-Banker master'!$H$2:$H$186,MATCH($J107,'E-Banker master'!$A$2:$A$186,0)),"") | N107: =IFERROR(INDEX('E-Banker master'!$I$2:$I$186,MATCH($J107,'E-Banker master'!$A$2:$A$186,0)),"") | O107: =IFERROR(INDEX('E-Banker master'!$N$2:$N$186,MATCH($J107,'E-Banker master'!$A$2:$A$186,0)),"") | P107: =IFERROR(INDEX('E-Banker master'!$P$2:$P$186,MATCH($J107,'E-Banker master'!$A$2:$A$186,0)),"") | Q107: =IFERROR(INDEX('E-Banker master'!$Q$2:$Q$186,MATCH($J107,'E-Banker master'!$A$2:$A$186,0)),"") | R107: =IFERROR(INDEX('E-Banker master'!$E$2:$E$186,MATCH($J107,'E-Banker master'!$A$2:$A$186,0)),"") | S107: =IF($J107="","",IF(O107="","No take-on posting",IF(ABS(H107-O107)<1,"Yes",IF(ABS(H107/O107-1)<0.01,"Within 1%","No")))) | T107: =IF($J107="","",IF(OR(P107="",P107=0),"No balance",IF(ABS(I107-P107)<1,"Yes",IF(ABS(I107/P107-1)<0.02,"Within 2%",IF(ABS(I107/P107-1)<0.05,"Within 5%","No"))))) | U107: =IF($J107="","",IF(N107="","",IF(ABS(F107-N107)<1,"Yes",IF(ABS(G107-N107)<1,"Disbursed = sanction","No")))) | V107: =IF(OR($J107="",Q107="",E107=""),"",ABS(E107-Q107)) | W107: No
A108: 114 | B108: ='Loan Book'!D114 | C108: ='Loan Book'!E114 | D108: ='Loan Book'!F114 | E108: ='Loan Book'!G114 | F108: ='Loan Book'!L114 | G108: ='Loan Book'!M114 | H108: ='Loan Book'!O114 | I108: ='Loan Book'!R114 | J108: 000104470000004 | K108: High | L108: =IFERROR(INDEX('E-Banker master'!$B$2:$B$186,MATCH($J108,'E-Banker master'!$A$2:$A$186,0)),"") | M108: =IFERROR(INDEX('E-Banker master'!$H$2:$H$186,MATCH($J108,'E-Banker master'!$A$2:$A$186,0)),"") | N108: =IFERROR(INDEX('E-Banker master'!$I$2:$I$186,MATCH($J108,'E-Banker master'!$A$2:$A$186,0)),"") | O108: =IFERROR(INDEX('E-Banker master'!$N$2:$N$186,MATCH($J108,'E-Banker master'!$A$2:$A$186,0)),"") | P108: =IFERROR(INDEX('E-Banker master'!$P$2:$P$186,MATCH($J108,'E-Banker master'!$A$2:$A$186,0)),"") | Q108: =IFERROR(INDEX('E-Banker master'!$Q$2:$Q$186,MATCH($J108,'E-Banker master'!$A$2:$A$186,0)),"") | R108: =IFERROR(INDEX('E-Banker master'!$E$2:$E$186,MATCH($J108,'E-Banker master'!$A$2:$A$186,0)),"") | S108: =IF($J108="","",IF(O108="","No take-on posting",IF(ABS(H108-O108)<1,"Yes",IF(ABS(H108/O108-1)<0.01,"Within 1%","No")))) | T108: =IF($J108="","",IF(OR(P108="",P108=0),"No balance",IF(ABS(I108-P108)<1,"Yes",IF(ABS(I108/P108-1)<0.02,"Within 2%",IF(ABS(I108/P108-1)<0.05,"Within 5%","No"))))) | U108: =IF($J108="","",IF(N108="","",IF(ABS(F108-N108)<1,"Yes",IF(ABS(G108-N108)<1,"Disbursed = sanction","No")))) | V108: =IF(OR($J108="",Q108="",E108=""),"",ABS(E108-Q108)) | W108: Yes
A109: 115 | B109: ='Loan Book'!D115 | C109: ='Loan Book'!E115 | D109: ='Loan Book'!F115 | E109: ='Loan Book'!G115 | F109: ='Loan Book'!L115 | G109: ='Loan Book'!M115 | H109: ='Loan Book'!O115 | I109: ='Loan Book'!R115 | J109: 000104430000057 | K109: High | L109: =IFERROR(INDEX('E-Banker master'!$B$2:$B$186,MATCH($J109,'E-Banker master'!$A$2:$A$186,0)),"") | M109: =IFERROR(INDEX('E-Banker master'!$H$2:$H$186,MATCH($J109,'E-Banker master'!$A$2:$A$186,0)),"") | N109: =IFERROR(INDEX('E-Banker master'!$I$2:$I$186,MATCH($J109,'E-Banker master'!$A$2:$A$186,0)),"") | O109: =IFERROR(INDEX('E-Banker master'!$N$2:$N$186,MATCH($J109,'E-Banker master'!$A$2:$A$186,0)),"") | P109: =IFERROR(INDEX('E-Banker master'!$P$2:$P$186,MATCH($J109,'E-Banker master'!$A$2:$A$186,0)),"") | Q109: =IFERROR(INDEX('E-Banker master'!$Q$2:$Q$186,MATCH($J109,'E-Banker master'!$A$2:$A$186,0)),"") | R109: =IFERROR(INDEX('E-Banker master'!$E$2:$E$186,MATCH($J109,'E-Banker master'!$A$2:$A$186,0)),"") | S109: =IF($J109="","",IF(O109="","No take-on posting",IF(ABS(H109-O109)<1,"Yes",IF(ABS(H109/O109-1)<0.01,"Within 1%","No")))) | T109: =IF($J109="","",IF(OR(P109="",P109=0),"No balance",IF(ABS(I109-P109)<1,"Yes",IF(ABS(I109/P109-1)<0.02,"Within 2%",IF(ABS(I109/P109-1)<0.05,"Within 5%","No"))))) | U109: =IF($J109="","",IF(N109="","",IF(ABS(F109-N109)<1,"Yes",IF(ABS(G109-N109)<1,"Disbursed = sanction","No")))) | V109: =IF(OR($J109="",Q109="",E109=""),"",ABS(E109-Q109)) | W109: Yes
A110: 116 | B110: ='Loan Book'!D116 | C110: ='Loan Book'!E116 | D110: ='Loan Book'!F116 | E110: ='Loan Book'!G116 | F110: ='Loan Book'!L116 | G110: ='Loan Book'!M116 | H110: ='Loan Book'!O116 | I110: ='Loan Book'!R116 | J110: 000104430000060 | K110: High | L110: =IFERROR(INDEX('E-Banker master'!$B$2:$B$186,MATCH($J110,'E-Banker master'!$A$2:$A$186,0)),"") | M110: =IFERROR(INDEX('E-Banker master'!$H$2:$H$186,MATCH($J110,'E-Banker master'!$A$2:$A$186,0)),"") | N110: =IFERROR(INDEX('E-Banker master'!$I$2:$I$186,MATCH($J110,'E-Banker master'!$A$2:$A$186,0)),"") | O110: =IFERROR(INDEX('E-Banker master'!$N$2:$N$186,MATCH($J110,'E-Banker master'!$A$2:$A$186,0)),"") | P110: =IFERROR(INDEX('E-Banker master'!$P$2:$P$186,MATCH($J110,'E-Banker master'!$A$2:$A$186,0)),"") | Q110: =IFERROR(INDEX('E-Banker master'!$Q$2:$Q$186,MATCH($J110,'E-Banker master'!$A$2:$A$186,0)),"") | R110: =IFERROR(INDEX('E-Banker master'!$E$2:$E$186,MATCH($J110,'E-Banker master'!$A$2:$A$186,0)),"") | S110: =IF($J110="","",IF(O110="","No take-on posting",IF(ABS(H110-O110)<1,"Yes",IF(ABS(H110/O110-1)<0.01,"Within 1%","No")))) | T110: =IF($J110="","",IF(OR(P110="",P110=0),"No balance",IF(ABS(I110-P110)<1,"Yes",IF(ABS(I110/P110-1)<0.02,"Within 2%",IF(ABS(I110/P110-1)<0.05,"Within 5%","No"))))) | U110: =IF($J110="","",IF(N110="","",IF(ABS(F110-N110)<1,"Yes",IF(ABS(G110-N110)<1,"Disbursed = sanction","No")))) | V110: =IF(OR($J110="",Q110="",E110=""),"",ABS(E110-Q110)) | W110: Yes
A112: Columns A to I are formulas into the 'Loan Book' sheet; L to R are lookups into 'E-Banker master' by the account in J; S to V are tests computed here; J, K and W are typed values from our matching (see Instructions). Yellow columns are for Tamanda.

Sheet Not matched
A1: Loan Book # | B1: Facility name | C1: Type | D1: Value date | E1: Approved | F1: Nearest candidates | G1: Tamanda: account number or 'no account' | H1: Comment
A2: 38 | B2: Favoured Farms | C2: Debt | D2: 2022-07-13 | E2: 10000000 | F2: 000104450000050 Greendom Farming (score 0.64); 000104450000038 Tac-Maz Investment (score 0.60); 000104450000015 Zaithwa Farms (score 0.58)
A3: 1 | B3: MMC Limited | C3: Equity | D3: 2022-12-23 | E3: 819476000 | F3: 000104450000085 MMC Limited (score 0.45); 000104450000034 MMM Investments (score 0.23); 000104420000005 MUSECO (score 0.16)
A4: 2 | B4: Wi Jays Enterprises | C4: Equity | D4: 2022-12-23 | E4: 177939650 | F4: 000104450000045 Walusiya Investment (score 0.19); 000104450000051 JAT Investments (score 0.19); 000106050000005 Wallie Farms (score 0.18)
A5: 3 | B5: Good Hope | C5: Equity | D5: 2023-03-31 | E5: 1500000000 | F5: 000106050000010 KWACHA Boutique HOTEL (score 0.27); 000104450000068 The Food Empire Limited (score 0.26); 000104420000043 The Food Empire Limited (score 0.21)

Sheet Accounts without a block
A1: E-Banker account | B1: E-Banker name | C1: Opening date | D1: Sanction | E1: Status | F1: Tamanda: which facility is this, or 'none' | G1: Comment
A2: 000104430000055 | B2: =IFERROR(INDEX('E-Banker master'!$B$2:$B$186,MATCH($A2,'E-Banker master'!$A$2:$A$186,0)),"") | C2: =IFERROR(INDEX('E-Banker master'!$H$2:$H$186,MATCH($A2,'E-Banker master'!$A$2:$A$186,0)),"") | D2: =IFERROR(INDEX('E-Banker master'!$I$2:$I$186,MATCH($A2,'E-Banker master'!$A$2:$A$186,0)),"") | E2: =IFERROR(INDEX('E-Banker master'!$E$2:$E$186,MATCH($A2,'E-Banker master'!$A$2:$A$186,0)),"")
A3: 000104430000056 | B3: =IFERROR(INDEX('E-Banker master'!$B$2:$B$186,MATCH($A3,'E-Banker master'!$A$2:$A$186,0)),"") | C3: =IFERROR(INDEX('E-Banker master'!$H$2:$H$186,MATCH($A3,'E-Banker master'!$A$2:$A$186,0)),"") | D3: =IFERROR(INDEX('E-Banker master'!$I$2:$I$186,MATCH($A3,'E-Banker master'!$A$2:$A$186,0)),"") | E3: =IFERROR(INDEX('E-Banker master'!$E$2:$E$186,MATCH($A3,'E-Banker master'!$A$2:$A$186,0)),"")
A4: 000104430000058 | B4: =IFERROR(INDEX('E-Banker master'!$B$2:$B$186,MATCH($A4,'E-Banker master'!$A$2:$A$186,0)),"") | C4: =IFERROR(INDEX('E-Banker master'!$H$2:$H$186,MATCH($A4,'E-Banker master'!$A$2:$A$186,0)),"") | D4: =IFERROR(INDEX('E-Banker master'!$I$2:$I$186,MATCH($A4,'E-Banker master'!$A$2:$A$186,0)),"") | E4: =IFERROR(INDEX('E-Banker master'!$E$2:$E$186,MATCH($A4,'E-Banker master'!$A$2:$A$186,0)),"")
A5: 000104430000059 | B5: =IFERROR(INDEX('E-Banker master'!$B$2:$B$186,MATCH($A5,'E-Banker master'!$A$2:$A$186,0)),"") | C5: =IFERROR(INDEX('E-Banker master'!$H$2:$H$186,MATCH($A5,'E-Banker master'!$A$2:$A$186,0)),"") | D5: =IFERROR(INDEX('E-Banker master'!$I$2:$I$186,MATCH($A5,'E-Banker master'!$A$2:$A$186,0)),"") | E5: =IFERROR(INDEX('E-Banker master'!$E$2:$E$186,MATCH($A5,'E-Banker master'!$A$2:$A$186,0)),"")
A6: 000104440000004 | B6: =IFERROR(INDEX('E-Banker master'!$B$2:$B$186,MATCH($A6,'E-Banker master'!$A$2:$A$186,0)),"") | C6: =IFERROR(INDEX('E-Banker master'!$H$2:$H$186,MATCH($A6,'E-Banker master'!$A$2:$A$186,0)),"") | D6: =IFERROR(INDEX('E-Banker master'!$I$2:$I$186,MATCH($A6,'E-Banker master'!$A$2:$A$186,0)),"") | E6: =IFERROR(INDEX('E-Banker master'!$E$2:$E$186,MATCH($A6,'E-Banker master'!$A$2:$A$186,0)),"")
A7: 000104460000058 | B7: =IFERROR(INDEX('E-Banker master'!$B$2:$B$186,MATCH($A7,'E-Banker master'!$A$2:$A$186,0)),"") | C7: =IFERROR(INDEX('E-Banker master'!$H$2:$H$186,MATCH($A7,'E-Banker master'!$A$2:$A$186,0)),"") | D7: =IFERROR(INDEX('E-Banker master'!$I$2:$I$186,MATCH($A7,'E-Banker master'!$A$2:$A$186,0)),"") | E7: =IFERROR(INDEX('E-Banker master'!$E$2:$E$186,MATCH($A7,'E-Banker master'!$A$2:$A$186,0)),"")
A8: 000104460000100 | B8: =IFERROR(INDEX('E-Banker master'!$B$2:$B$186,MATCH($A8,'E-Banker master'!$A$2:$A$186,0)),"") | C8: =IFERROR(INDEX('E-Banker master'!$H$2:$H$186,MATCH($A8,'E-Banker master'!$A$2:$A$186,0)),"") | D8: =IFERROR(INDEX('E-Banker master'!$I$2:$I$186,MATCH($A8,'E-Banker master'!$A$2:$A$186,0)),"") | E8: =IFERROR(INDEX('E-Banker master'!$E$2:$E$186,MATCH($A8,'E-Banker master'!$A$2:$A$186,0)),"")
A9: 000104460000101 | B9: =IFERROR(INDEX('E-Banker master'!$B$2:$B$186,MATCH($A9,'E-Banker master'!$A$2:$A$186,0)),"") | C9: =IFERROR(INDEX('E-Banker master'!$H$2:$H$186,MATCH($A9,'E-Banker master'!$A$2:$A$186,0)),"") | D9: =IFERROR(INDEX('E-Banker master'!$I$2:$I$186,MATCH($A9,'E-Banker master'!$A$2:$A$186,0)),"") | E9: =IFERROR(INDEX('E-Banker master'!$E$2:$E$186,MATCH($A9,'E-Banker master'!$A$2:$A$186,0)),"")

Sheet Upload summary
A1: E-Banker account | B1: Confidence | C1: Loan Book row | D1: Facility name | E1: Type | F1: Value date | G1: Maturity date | H1: Tenor (years) | I1: Moratorium (text) | J1: Rate 31 Oct 2024 % | K1: Approved | L1: Disbursed | M1: Not yet disbursed | N1: Principal 31 Oct 2024 | O1: Interest to date | P1: Repayments | Q1: Carrying amount 31 Oct 2024 | R1: Arrears principal | S1: Arrears interest | T1: Arrears total | U1: Segment | V1: Industry | W1: E-Banker name | X1: Scheme id | Y1: GL code | Z1: Status | AA1: Interest policy | AB1: Rate now % | AC1: Sanction | AD1: Sanction date | AE1: Expiry | AF1: P moratorium | AG1: I moratorium | AH1: Take-on posting 31 Jul 2024 | AI1: Opening interest 31 Jul 2024 | AJ1: Balance 31 Oct 2024 | AK1: Carrying amount less balance | AL1: Block # | AM1: Go to block | AN1: Tamanda confirmed (from Mapping) | AO1: Arrangement fee (MK) | AP1: Legal fees (MK) | AQ1: Other integral fees (MK) | AR1: Fee date (dd/mm/yyyy) | AS1: Deducted from disbursement? (Y/N) | AT1: Source (offer letter ref or receipt) | AU1: Total fees (MK)
A2: ='Mapping'!J2 | B2: ='Mapping'!K2 | C2: 5 | D2: ='Loan Book'!E5 | E2: ='Loan Book'!F5 | F2: ='Loan Book'!G5 | G2: ='Loan Book'!H5 | H2: ='Loan Book'!I5 | I2: ='Loan Book'!J5 | J2: =IF('Loan Book'!K5="","",IF('Loan Book'!K5<1,'Loan Book'!K5*100,'Loan Book'!K5)) | K2: ='Loan Book'!L5 | L2: ='Loan Book'!M5 | M2: ='Loan Book'!N5 | N2: ='Loan Book'!O5 | O2: ='Loan Book'!P5 | P2: ='Loan Book'!Q5 | Q2: ='Loan Book'!R5 | R2: ='Loan Book'!S5 | ... T2: ='Loan Book'!U5 | U2: ='Loan Book'!AC5 | V2: ='Loan Book'!AE5 | W2: =IFERROR(INDEX('E-Banker master'!$B$2:$B$186,MATCH($A2,'E-Banker master'!$A$2:$A$186,0)),"") | X2: =IFERROR(INDEX('E-Banker master'!$C$2:$C$186,MATCH($A2,'E-Banker master'!$A$2:$A$186,0)),"") | Y2: =IFERROR(INDEX('E-Banker master'!$D$2:$D$186,MATCH($A2,'E-Banker master'!$A$2:$A$186,0)),"") | Z2: =IFERROR(INDEX('E-Banker master'!$E$2:$E$186,MATCH($A2,'E-Banker master'!$A$2:$A$186,0)),"") | AA2: =IFERROR(INDEX('E-Banker master'!$F$2:$F$186,MATCH($A2,'E-Banker master'!$A$2:$A$186,0)),"") | AB2: =IFERROR(INDEX('E-Banker master'!$G$2:$G$186,MATCH($A2,'E-Banker master'!$A$2:$A$186,0)),"") | AC2: =IFERROR(INDEX('E-Banker master'!$I$2:$I$186,MATCH($A2,'E-Banker master'!$A$2:$A$186,0)),"") | AD2: =IFERROR(INDEX('E-Banker master'!$J$2:$J$186,MATCH($A2,'E-Banker master'!$A$2:$A$186,0)),"") | AE2: =IFERROR(INDEX('E-Banker master'!$K$2:$K$186,MATCH($A2,'E-Banker master'!$A$2:$A$186,0)),"") | AF2: =IFERROR(INDEX('E-Banker master'!$L$2:$L$186,MATCH($A2,'E-Banker master'!$A$2:$A$186,0)),"") | AG2: =IFERROR(INDEX('E-Banker master'!$M$2:$M$186,MATCH($A2,'E-Banker master'!$A$2:$A$186,0)),"") | AH2: =IFERROR(INDEX('E-Banker master'!$N$2:$N$186,MATCH($A2,'E-Banker master'!$A$2:$A$186,0)),"") | AI2: =IFERROR(INDEX('E-Banker master'!$O$2:$O$186,MATCH($A2,'E-Banker master'!$A$2:$A$186,0)),"") | AJ2: =IFERROR(INDEX('E-Banker master'!$P$2:$P$186,MATCH($A2,'E-Banker master'!$A$2:$A$186,0)),"") | AK2: =IF(OR(Q2="",AJ2=""),"",Q2-AJ2) | AL2: 1 | AM2: =HYPERLINK("#'Amortisation and Repayments'!C4","block 1") | AN2: ='Mapping'!X2 | AU2: =IF(COUNT(AO2:AQ2)=0,"",SUM(AO2:AQ2))
